Workbook

Sheet table_1
A1: model | B1: run | C1: frequency | D1: role | E1: detector | F1: base_run | G1: full_cum_return | H1: full_cagr | I1: full_ann_vol | J1: full_sharpe | K1: full_sortino | L1: full_calmar | M1: full_max_dd | N1: full_ulcer | O1: full_turnover_pa | P1: ret_outside_crises_ann | Q1: sharpe_outside_crises | R1: sharpe_inside_crises | S1: fix_hit_count_full | T1: fix_hit_count_ptt | U1: fix_hit_count_ttp | V1: flex_hit_count_full | W1: flex_hit_count_ptt | X1: flex_hit_count_ttp
A2: market_cap | B2: mcap_t_10 | C2: monthly | D2: benchmark | E2: none | G2: 15.230356 | H2: 0.10487192 | I2: 0.2031245 | J2: 0.38772028 | K2: 0.54435196 | L2: 0.2003908 | M2: -0.52333703 | N2: 0.1851086 | O2: 0.16185453 | P2: 0.25093651 | Q2: 1.2384941 | R2: -0.060212669
A3: equal_weight | B3: equal_t_10 | C3: monthly | D3: baseline | E3: none | F3: equal_t_10 | G3: 13.595801 | H3: 0.10068293 | I3: 0.19701639 | J3: 0.38046618 | K3: 0.53332048 | L3: 0.18100431 | M3: -0.55624605 | N3: 0.14437033 | O3: 0.76638353 | P3: 0.22594841 | Q3: 1.2077458 | R3: -0.023964276 | S3: 3/6 | T3: 4/6 | U3: 3/6 | V3: 4/6 | W3: 4/6 | X3: 3/6
A4: mvo | B4: mvo_t_10_lw | C4: monthly | D4: baseline | E4: none | F4: mvo_t_10_lw | G4: 12.773208 | H4: 0.098400444 | I4: 0.19353753 | J4: 0.37657016 | K4: 0.52883062 | L4: 0.18202492 | M4: -0.54058775 | N4: 0.20219585 | O4: 2.0899231 | P4: 0.22989216 | Q4: 1.1294217 | R4: -0.053648663 | S4: 2/6 | T4: 3/6 | U4: 2/6 | V4: 3/6 | W4: 3/6 | X4: 2/5
A5: hrp | B5: hrp_t_10_lw_ward | C5: monthly | D5: baseline | E5: none | F5: hrp_t_10_lw_ward | G5: 11.342476 | H5: 0.094097801 | I5: 0.17172193 | J5: 0.40155689 | K5: 0.5652819 | L5: 0.20644651 | M5: -0.45579748 | N5: 0.10490304 | O5: 1.2952811 | P5: 0.18321647 | Q5: 1.0706662 | R5: 0.054045434 | S5: 2/6 | T5: 5/6 | U5: 2/6 | V5: 5/6 | W5: 5/6 | X5: 4/6
A6: xgb | B6: xgb_t_10_holdout | C6: monthly | D6: baseline | E6: none | F6: xgb_t_10_holdout | G6: 14.77345 | H6: 0.10374348 | I6: 0.21674807 | J6: 0.35864712 | K6: 0.50350775 | L6: 0.16847619 | M6: -0.61577533 | N6: 0.154927 | O6: 5.4942424 | P6: 0.23339039 | Q6: 1.1964281 | R6: -0.019999202 | S6: 3/6 | T6: 3/6 | U6: 3/6 | V6: 4/6 | W6: 3/6 | X6: 3/6
A7: rf | B7: rf_t_10_holdout | C7: monthly | D7: baseline | E7: none | F7: rf_t_10_holdout | G7: 15.337051 | H7: 0.10513102 | I7: 0.21949509 | J7: 0.35988318 | K7: 0.50486586 | L7: 0.17234589 | M7: -0.61000017 | N7: 0.1598728 | O7: 4.8293763 | P7: 0.23484083 | Q7: 1.182935 | R7: -0.014594414 | S7: 4/6 | T7: 3/6 | U7: 4/6 | V7: 4/6 | W7: 3/6 | X7: 4/6
A8: lstm | B8: lstm_t_10_holdout_rank | C8: monthly | D8: baseline | E8: none | F8: lstm_t_10_holdout_rank | G8: 15.946816 | H8: 0.10658116 | I8: 0.21836728 | J8: 0.36774436 | K8: 0.51543333 | L8: 0.173398 | M8: -0.61466199 | N8: 0.1667251 | O8: 3.3601865 | P8: 0.23522846 | Q8: 1.1935436 | R8: -0.0065566178 | S8: 3/6 | T8: 3/6 | U8: 3/6 | V8: 4/6 | W8: 3/6 | X8: 3/6

Sheet table_2
A1: Crises | B1: Equal_Weighted | C1: Drawdown_Weighted | D1: Duration_Weighted | E1: VIX_Weighted
A2: C1 | B2: 0.1667 | C2: 0.241 | D2: 0.4884 | E2: 0.1455
A3: C2 | B3: 0.1667 | C3: 0.2784 | D3: 0.2715 | E3: 0.1881
A4: C3 | B4: 0.1667 | C4: 0.0968 | D4: 0.0494 | E4: 0.1139
A5: C4 | B5: 0.1667 | C5: 0.1663 | D5: 0.0173 | E5: 0.2672
A6: C5 | B6: 0.1667 | C6: 0.1247 | D6: 0.1481 | E6: 0.1498
A7: C6 | B7: 0.1667 | C7: 0.0927 | D7: 0.0252 | E7: 0.1355
A12: Equal Weighted Crises | B12: Baselines only
A13: model | B13: run | C13: frequency | D13: role | E13: detector | F13: base_run | G13: avg_crisis_exc_ret_full_fix | H13: avg_crisis_exc_dd_full_fix | I13: avg_crisis_exc_dd_full_flex | J13: avg_crisis_exc_days_full_flex | K13: avg_crisis_exc_ulcer_full_flex | L13: avg_crisis_exc_ret_ptt_fix | M13: avg_crisis_exc_dd_ptt_fix | N13: avg_crisis_exc_days_ptt_flex | O13: avg_crisis_exc_ret_ttp_fix | P13: avg_crisis_exc_dd_ttp_fix | Q13: avg_crisis_exc_days_ttp_flex | R13: avg_exc_crisis_ret_to_even_ttp_flex
A14: market_cap | B14: mcap_t_10 | C14: monthly | D14: benchmark | E14: none | G14: =SUM(crises_vs_mcap!J2*$B$2+crises_vs_mcap!K2*$B$3+crises_vs_mcap!L2*$B$4+crises_vs_mcap!M2*$B$5+crises_vs_mcap!N2*$B$6+crises_vs_mcap!O2*$B$7) -> 0 | H14: =SUM(crises_vs_mcap!P2*$B$2+crises_vs_mcap!Q2*$B$3+crises_vs_mcap!R2*$B$4+crises_vs_mcap!S2*$B$5+crises_vs_mcap!T2*$B$6+crises_vs_mcap!U2*$B$7) -> 0 | I14: =SUM(crises_vs_mcap!AB2*$B$2+crises_vs_mcap!AC2*$B$3+crises_vs_mcap!AD2*$B$4+crises_vs_mcap!AE2*$B$5+crises_vs_mcap!AF2*$B$6+crises_vs_mcap!AG2*$B$7) -> 0 | J14: =(N(crises_vs_mcap!AH2)*$B$2+N(crises_vs_mcap!AI2)*$B$3+N(crises_vs_mcap!AJ2)*$B$4+N(crises_vs_mcap!AK2)*$B$5+N(crises_vs_mcap!AL2)*$B$6+N(crises_vs_mcap!AM2)*$B$7) /(ISNUMBER(crises_vs_mcap!AH2)*$B$2+ISNUMBER(crises_vs_mcap!AI2)*$B$3+ISNUMBER(crises_vs_mcap!AJ2)*$B$4+ISNUMBER(crises_vs_mcap!AK2)*$B$5+ISNUMBER(crises_vs_mcap!AL2)*$B$6+ISNUMBER(crises_vs_mcap!AM2)*$B$7) -> 0 | K14: =SUM(crises_vs_mcap!AZ2*$B$2+crises_vs_mcap!BA2*$B$3+crises_vs_mcap!BB2*$B$4+crises_vs_mcap!BC2*$B$5+crises_vs_mcap!BD2*$B$6+crises_vs_mcap!BE2*$B$7) -> 0 | L14: =SUM(crises_vs_mcap!BL2*$B$2+crises_vs_mcap!BM2*$B$3+crises_vs_mcap!BN2*$B$4+crises_vs_mcap!BO2*$B$5+crises_vs_mcap!BP2*$B$6+crises_vs_mcap!BQ2*$B$7) -> 0 | M14: =SUM(crises_vs_mcap!BR2*$B$2+crises_vs_mcap!BS2*$B$3+crises_vs_mcap!BT2*$B$4+crises_vs_mcap!BU2*$B$5+crises_vs_mcap!BV2*$B$6+crises_vs_mcap!BW2*$B$7) -> 0 | N14: =SUM(crises_vs_mcap!BX2*$B$2+crises_vs_mcap!BY2*$B$3+crises_vs_mcap!BZ2*$B$4+crises_vs_mcap!CA2*$B$5+crises_vs_mcap!CB2*$B$6+crises_vs_mcap!CC2*$B$7) -> 0 | O14: =SUM(crises_vs_mcap!CD2*$B$2+crises_vs_mcap!CE2*$B$3+crises_vs_mcap!CF2*$B$4+crises_vs_mcap!CG2*$B$5+crises_vs_mcap!CH2*$B$6+crises_vs_mcap!CI2*$B$7) -> 0 | P14: =SUM(crises_vs_mcap!CJ2*$B$2+crises_vs_mcap!CK2*$B$3+crises_vs_mcap!CL2*$B$4+crises_vs_mcap!CM2*$B$5+crises_vs_mcap!CN2*$B$6+crises_vs_mcap!CO2*$B$7) -> 0 | Q14: =(N(crises_vs_mcap!CP2)*$B$2+N(crises_vs_mcap!CQ2)*$B$3+N(crises_vs_mcap!CR2)*$B$4+N(crises_vs_mcap!CS2)*$B$5+N(crises_vs_mcap!CT2)*$B$6+N(crises_vs_mcap!CU2)*$B$7)/(ISNUMBER(crises_vs_mcap!CP2)*$B$2+ISNUMBER(crises_vs_mcap!CQ2)*$B$3+ISNUMBER(crises_vs_mcap!CR2)*$B$4+ISNUMBER(crises_vs_mcap!CS2)*$B$5+ISNUMBER(crises_vs_mcap!CT2)*$B$6+ISNUMBER(crises_vs_mcap!CU2)*$B$7) -> 0 | R14: =SUM(crises_vs_mcap!CV2*$B$2+crises_vs_mcap!CW2*$B$3+crises_vs_mcap!CX2*$B$4+crises_vs_mcap!CY2*$B$5+crises_vs_mcap!CZ2*$B$6+crises_vs_mcap!DA2*$B$7) -> 0
A15: equal_weight | B15: equal_t_10 | C15: monthly | D15: baseline | E15: none | F15: equal_t_10 | G15: =SUM(crises_vs_mcap!J3*$B$2+crises_vs_mcap!K3*$B$3+crises_vs_mcap!L3*$B$4+crises_vs_mcap!M3*$B$5+crises_vs_mcap!N3*$B$6+crises_vs_mcap!O3*$B$7) -> 0.027620566 | H15: =SUM(crises_vs_mcap!P3*$B$2+crises_vs_mcap!Q3*$B$3+crises_vs_mcap!R3*$B$4+crises_vs_mcap!S3*$B$5+crises_vs_mcap!T3*$B$6+crises_vs_mcap!U3*$B$7) -> 0.021507022 | I15: =SUM(crises_vs_mcap!AB3*$B$2+crises_vs_mcap!AC3*$B$3+crises_vs_mcap!AD3*$B$4+crises_vs_mcap!AE3*$B$5+crises_vs_mcap!AF3*$B$6+crises_vs_mcap!AG3*$B$7) -> 0.023659839 | J15: =(N(crises_vs_mcap!AH3)*$B$2+N(crises_vs_mcap!AI3)*$B$3+N(crises_vs_mcap!AJ3)*$B$4+N(crises_vs_mcap!AK3)*$B$5+N(crises_vs_mcap!AL3)*$B$6+N(crises_vs_mcap!AM3)*$B$7) /(ISNUMBER(crises_vs_mcap!AH3)*$B$2+ISNUMBER(crises_vs_mcap!AI3)*$B$3+ISNUMBER(crises_vs_mcap!AJ3)*$B$4+ISNUMBER(crises_vs_mcap!AK3)*$B$5+ISNUMBER(crises_vs_mcap!AL3)*$B$6+ISNUMBER(crises_vs_mcap!AM3)*$B$7) -> 15 | K15: =SUM(crises_vs_mcap!AZ3*$B$2+crises_vs_mcap!BA3*$B$3+crises_vs_mcap!BB3*$B$4+crises_vs_mcap!BC3*$B$5+crises_vs_mcap!BD3*$B$6+crises_vs_mcap!BE3*$B$7) -> -0.0234268 | L15: =SUM(crises_vs_mcap!BL3*$B$2+crises_vs_mcap!BM3*$B$3+crises_vs_mcap!BN3*$B$4+crises_vs_mcap!BO3*$B$5+crises_vs_mcap!BP3*$B$6+crises_vs_mcap!BQ3*$B$7) -> 0.029642638 | M15: =SUM(crises_vs_mcap!BR3*$B$2+crises_vs_mcap!BS3*$B$3+crises_vs_mcap!BT3*$B$4+crises_vs_mcap!BU3*$B$5+crises_vs_mcap!BV3*$B$6+crises_vs_mcap!BW3*$B$7) -> 0.019151629 | N15: =SUM(crises_vs_mcap!BX3*$B$2+crises_vs_mcap!BY3*$B$3+crises_vs_mcap!BZ3*$B$4+crises_vs_mcap!CA3*$B$5+crises_vs_mcap!CB3*$B$6+crises_vs_mcap!CC3*$B$7) -> -9.6686 | O15: =SUM(crises_vs_mcap!CD3*$B$2+crises_vs_mcap!CE3*$B$3+crises_vs_mcap!CF3*$B$4+crises_vs_mcap!CG3*$B$5+crises_vs_mcap!CH3*$B$6+crises_vs_mcap!CI3*$B$7) -> -0.0016782381 | P15: =SUM(crises_vs_mcap!CJ3*$B$2+crises_vs_mcap!CK3*$B$3+crises_vs_mcap!CL3*$B$4+crises_vs_mcap!CM3*$B$5+crises_vs_mcap!CN3*$B$6+crises_vs_mcap!CO3*$B$7) -> 0.00025483414 | Q15: =(N(crises_vs_mcap!CP3)*$B$2+N(crises_vs_mcap!CQ3)*$B$3+N(crises_vs_mcap!CR3)*$B$4+N(crises_vs_mcap!CS3)*$B$5+N(crises_vs_mcap!CT3)*$B$6+N(crises_vs_mcap!CU3)*$B$7)/(ISNUMBER(crises_vs_mcap!CP3)*$B$2+ISNUMBER(crises_vs_mcap!CQ3)*$B$3+ISNUMBER(crises_vs_mcap!CR3)*$B$4+ISNUMBER(crises_vs_mcap!CS3)*$B$5+ISNUMBER(crises_vs_mcap!CT3)*$B$6+ISNUMBER(crises_vs_mcap!CU3)*$B$7) -> 26.6 | R15: =SUM(crises_vs_mcap!CV3*$B$2+crises_vs_mcap!CW3*$B$3+crises_vs_mcap!CX3*$B$4+crises_vs_mcap!CY3*$B$5+crises_vs_mcap!CZ3*$B$6+crises_vs_mcap!DA3*$B$7) -> -0.041159272
A16: mvo | B16: mvo_t_10_lw | C16: monthly | D16: baseline | E16: none | F16: mvo_t_10_lw | G16: =SUM(crises_vs_mcap!J4*$B$2+crises_vs_mcap!K4*$B$3+crises_vs_mcap!L4*$B$4+crises_vs_mcap!M4*$B$5+crises_vs_mcap!N4*$B$6+crises_vs_mcap!O4*$B$7) -> 0.0096665159 | H16: =SUM(crises_vs_mcap!P4*$B$2+crises_vs_mcap!Q4*$B$3+crises_vs_mcap!R4*$B$4+crises_vs_mcap!S4*$B$5+crises_vs_mcap!T4*$B$6+crises_vs_mcap!U4*$B$7) -> 0.008537705 | I16: =SUM(crises_vs_mcap!AB4*$B$2+crises_vs_mcap!AC4*$B$3+crises_vs_mcap!AD4*$B$4+crises_vs_mcap!AE4*$B$5+crises_vs_mcap!AF4*$B$6+crises_vs_mcap!AG4*$B$7) -> 0.0097933187 | J16: =(N(crises_vs_mcap!AH4)*$B$2+N(crises_vs_mcap!AI4)*$B$3+N(crises_vs_mcap!AJ4)*$B$4+N(crises_vs_mcap!AK4)*$B$5+N(crises_vs_mcap!AL4)*$B$6+N(crises_vs_mcap!AM4)*$B$7) /(ISNUMBER(crises_vs_mcap!AH4)*$B$2+ISNUMBER(crises_vs_mcap!AI4)*$B$3+ISNUMBER(crises_vs_mcap!AJ4)*$B$4+ISNUMBER(crises_vs_mcap!AK4)*$B$5+ISNUMBER(crises_vs_mcap!AL4)*$B$6+ISNUMBER(crises_vs_mcap!AM4)*$B$7) -> -82 | K16: =SUM(crises_vs_mcap!AZ4*$B$2+crises_vs_mcap!BA4*$B$3+crises_vs_mcap!BB4*$B$4+crises_vs_mcap!BC4*$B$5+crises_vs_mcap!BD4*$B$6+crises_vs_mcap!BE4*$B$7) -> 0.0016740791 | L16: =SUM(crises_vs_mcap!BL4*$B$2+crises_vs_mcap!BM4*$B$3+crises_vs_mcap!BN4*$B$4+crises_vs_mcap!BO4*$B$5+crises_vs_mcap!BP4*$B$6+crises_vs_mcap!BQ4*$B$7) -> 0.013410217 | M16: =SUM(crises_vs_mcap!BR4*$B$2+crises_vs_mcap!BS4*$B$3+crises_vs_mcap!BT4*$B$4+crises_vs_mcap!BU4*$B$5+crises_vs_mcap!BV4*$B$6+crises_vs_mcap!BW4*$B$7) -> 0.0068174984 | N16: =SUM(crises_vs_mcap!BX4*$B$2+crises_vs_mcap!BY4*$B$3+crises_vs_mcap!BZ4*$B$4+crises_vs_mcap!CA4*$B$5+crises_vs_mcap!CB4*$B$6+crises_vs_mcap!CC4*$B$7) -> -0.3334 | O16: =SUM(crises_vs_mcap!CD4*$B$2+crises_vs_mcap!CE4*$B$3+crises_vs_mcap!CF4*$B$4+crises_vs_mcap!CG4*$B$5+crises_vs_mcap!CH4*$B$6+crises_vs_mcap!CI4*$B$7) -> -0.0038813381 | P16: =SUM(crises_vs_mcap!CJ4*$B$2+crises_vs_mcap!CK4*$B$3+crises_vs_mcap!CL4*$B$4+crises_vs_mcap!CM4*$B$5+crises_vs_mcap!CN4*$B$6+crises_vs_mcap!CO4*$B$7) -> 0.0091332807 | Q16: =(N(crises_vs_mcap!CP4)*$B$2+N(crises_vs_mcap!CQ4)*$B$3+N(crises_vs_mcap!CR4)*$B$4+N(crises_vs_mcap!CS4)*$B$5+N(crises_vs_mcap!CT4)*$B$6+N(crises_vs_mcap!CU4)*$B$7)/(ISNUMBER(crises_vs_mcap!CP4)*$B$2+ISNUMBER(crises_vs_mcap!CQ4)*$B$3+ISNUMBER(crises_vs_mcap!CR4)*$B$4+ISNUMBER(crises_vs_mcap!CS4)*$B$5+ISNUMBER(crises_vs_mcap!CT4)*$B$6+ISNUMBER(crises_vs_mcap!CU4)*$B$7) -> -81.6 | R16: =SUM(crises_vs_mcap!CV4*$B$2+crises_vs_mcap!CW4*$B$3+crises_vs_mcap!CX4*$B$4+crises_vs_mcap!CY4*$B$5+crises_vs_mcap!CZ4*$B$6+crises_vs_mcap!DA4*$B$7) -> -0.017203458
A17: hrp | B17: hrp_t_10_lw_ward | C17: monthly | D17: baseline | E17: none | F17: hrp_t_10_lw_ward | G17: =SUM(crises_vs_mcap!J5*$B$2+crises_vs_mcap!K5*$B$3+crises_vs_mcap!L5*$B$4+crises_vs_mcap!M5*$B$5+crises_vs_mcap!N5*$B$6+crises_vs_mcap!O5*$B$7) -> 0.080705334 | H17: =SUM(crises_vs_mcap!P5*$B$2+crises_vs_mcap!Q5*$B$3+crises_vs_mcap!R5*$B$4+crises_vs_mcap!S5*$B$5+crises_vs_mcap!T5*$B$6+crises_vs_mcap!U5*$B$7) -> 0.066932689 | I17: =SUM(crises_vs_mcap!AB5*$B$2+crises_vs_mcap!AC5*$B$3+crises_vs_mcap!AD5*$B$4+crises_vs_mcap!AE5*$B$5+crises_vs_mcap!AF5*$B$6+crises_vs_mcap!AG5*$B$7) -> 0.07281429 | J17: =(N(crises_vs_mcap!AH5)*$B$2+N(crises_vs_mcap!AI5)*$B$3+N(crises_vs_mcap!AJ5)*$B$4+N(crises_vs_mcap!AK5)*$B$5+N(crises_vs_mcap!AL5)*$B$6+N(crises_vs_mcap!AM5)*$B$7) /(ISNUMBER(crises_vs_mcap!AH5)*$B$2+ISNUMBER(crises_vs_mcap!AI5)*$B$3+ISNUMBER(crises_vs_mcap!AJ5)*$B$4+ISNUMBER(crises_vs_mcap!AK5)*$B$5+ISNUMBER(crises_vs_mcap!AL5)*$B$6+ISNUMBER(crises_vs_mcap!AM5)*$B$7) -> -30 | K17: =SUM(crises_vs_mcap!AZ5*$B$2+crises_vs_mcap!BA5*$B$3+crises_vs_mcap!BB5*$B$4+crises_vs_mcap!BC5*$B$5+crises_vs_mcap!BD5*$B$6+crises_vs_mcap!BE5*$B$7) -> -0.047013322 | L17: =SUM(crises_vs_mcap!BL5*$B$2+crises_vs_mcap!BM5*$B$3+crises_vs_mcap!BN5*$B$4+crises_vs_mcap!BO5*$B$5+crises_vs_mcap!BP5*$B$6+crises_vs_mcap!BQ5*$B$7) -> 0.12407229 | M17: =SUM(crises_vs_mcap!BR5*$B$2+crises_vs_mcap!BS5*$B$3+crises_vs_mcap!BT5*$B$4+crises_vs_mcap!BU5*$B$5+crises_vs_mcap!BV5*$B$6+crises_vs_mcap!BW5*$B$7) -> 0.064577295 | N17: =SUM(crises_vs_mcap!BX5*$B$2+crises_vs_mcap!BY5*$B$3+crises_vs_mcap!BZ5*$B$4+crises_vs_mcap!CA5*$B$5+crises_vs_mcap!CB5*$B$6+crises_vs_mcap!CC5*$B$7) -> -9.6686 | O17: =SUM(crises_vs_mcap!CD5*$B$2+crises_vs_mcap!CE5*$B$3+crises_vs_mcap!CF5*$B$4+crises_vs_mcap!CG5*$B$5+crises_vs_mcap!CH5*$B$6+crises_vs_mcap!CI5*$B$7) -> -0.042626222 | P17: =SUM(crises_vs_mcap!CJ5*$B$2+crises_vs_mcap!CK5*$B$3+crises_vs_mcap!CL5*$B$4+crises_vs_mcap!CM5*$B$5+crises_vs_mcap!CN5*$B$6+crises_vs_mcap!CO5*$B$7) -> 0.015737388 | Q17: =(N(crises_vs_mcap!CP5)*$B$2+N(crises_vs_mcap!CQ5)*$B$3+N(crises_vs_mcap!CR5)*$B$4+N(crises_vs_mcap!CS5)*$B$5+N(crises_vs_mcap!CT5)*$B$6+N(crises_vs_mcap!CU5)*$B$7)/(ISNUMBER(crises_vs_mcap!CP5)*$B$2+ISNUMBER(crises_vs_mcap!CQ5)*$B$3+ISNUMBER(crises_vs_mcap!CR5)*$B$4+ISNUMBER(crises_vs_mcap!CS5)*$B$5+ISNUMBER(crises_vs_mcap!CT5)*$B$6+ISNUMBER(crises_vs_mcap!CU5)*$B$7) -> -18.4 | R17: =SUM(crises_vs_mcap!CV5*$B$2+crises_vs_mcap!CW5*$B$3+crises_vs_mcap!CX5*$B$4+crises_vs_mcap!CY5*$B$5+crises_vs_mcap!CZ5*$B$6+crises_vs_mcap!DA5*$B$7) -> -0.17173292
A18: xgb | B18: xgb_t_10_holdout | C18: monthly | D18: baseline | E18: none | F18: xgb_t_10_holdout | G18: =SUM(crises_vs_mcap!J6*$B$2+crises_vs_mcap!K6*$B$3+crises_vs_mcap!L6*$B$4+crises_vs_mcap!M6*$B$5+crises_vs_mcap!N6*$B$6+crises_vs_mcap!O6*$B$7) -> 0.03077339 | H18: =SUM(crises_vs_mcap!P6*$B$2+crises_vs_mcap!Q6*$B$3+crises_vs_mcap!R6*$B$4+crises_vs_mcap!S6*$B$5+crises_vs_mcap!T6*$B$6+crises_vs_mcap!U6*$B$7) -> 0.0014335506 | I18: =SUM(crises_vs_mcap!AB6*$B$2+crises_vs_mcap!AC6*$B$3+crises_vs_mcap!AD6*$B$4+crises_vs_mcap!AE6*$B$5+crises_vs_mcap!AF6*$B$6+crises_vs_mcap!AG6*$B$7) -> 0.0029887509 | J18: =(N(crises_vs_mcap!AH6)*$B$2+N(crises_vs_mcap!AI6)*$B$3+N(crises_vs_mcap!AJ6)*$B$4+N(crises_vs_mcap!AK6)*$B$5+N(crises_vs_mcap!AL6)*$B$6+N(crises_vs_mcap!AM6)*$B$7) /(ISNUMBER(crises_vs_mcap!AH6)*$B$2+ISNUMBER(crises_vs_mcap!AI6)*$B$3+ISNUMBER(crises_vs_mcap!AJ6)*$B$4+ISNUMBER(crises_vs_mcap!AK6)*$B$5+ISNUMBER(crises_vs_mcap!AL6)*$B$6+ISNUMBER(crises_vs_mcap!AM6)*$B$7) -> 22.4 | K18: =SUM(crises_vs_mcap!AZ6*$B$2+crises_vs_mcap!BA6*$B$3+crises_vs_mcap!BB6*$B$4+crises_vs_mcap!BC6*$B$5+crises_vs_mcap!BD6*$B$6+crises_vs_mcap!BE6*$B$7) -> -0.017010607 | L18: =SUM(crises_vs_mcap!BL6*$B$2+crises_vs_mcap!BM6*$B$3+crises_vs_mcap!BN6*$B$4+crises_vs_mcap!BO6*$B$5+crises_vs_mcap!BP6*$B$6+crises_vs_mcap!BQ6*$B$7) -> -0.0062112049 | M18: =SUM(crises_vs_mcap!BR6*$B$2+crises_vs_mcap!BS6*$B$3+crises_vs_mcap!BT6*$B$4+crises_vs_mcap!BU6*$B$5+crises_vs_mcap!BV6*$B$6+crises_vs_mcap!BW6*$B$7) -> -0.00085195853 | N18: =SUM(crises_vs_mcap!BX6*$B$2+crises_vs_mcap!BY6*$B$3+crises_vs_mcap!BZ6*$B$4+crises_vs_mcap!CA6*$B$5+crises_vs_mcap!CB6*$B$6+crises_vs_mcap!CC6*$B$7) -> -0.5001 | O18: =SUM(crises_vs_mcap!CD6*$B$2+crises_vs_mcap!CE6*$B$3+crises_vs_mcap!CF6*$B$4+crises_vs_mcap!CG6*$B$5+crises_vs_mcap!CH6*$B$6+crises_vs_mcap!CI6*$B$7) -> 0.041446516 | P18: =SUM(crises_vs_mcap!CJ6*$B$2+crises_vs_mcap!CK6*$B$3+crises_vs_mcap!CL6*$B$4+crises_vs_mcap!CM6*$B$5+crises_vs_mcap!CN6*$B$6+crises_vs_mcap!CO6*$B$7) -> -0.01466919 | Q18: =(N(crises_vs_mcap!CP6)*$B$2+N(crises_vs_mcap!CQ6)*$B$3+N(crises_vs_mcap!CR6)*$B$4+N(crises_vs_mcap!CS6)*$B$5+N(crises_vs_mcap!CT6)*$B$6+N(crises_vs_mcap!CU6)*$B$7)/(ISNUMBER(crises_vs_mcap!CP6)*$B$2+ISNUMBER(crises_vs_mcap!CQ6)*$B$3+ISNUMBER(crises_vs_mcap!CR6)*$B$4+ISNUMBER(crises_vs_mcap!CS6)*$B$5+ISNUMBER(crises_vs_mcap!CT6)*$B$6+ISNUMBER(crises_vs_mcap!CU6)*$B$7) -> 34 | R18: =SUM(crises_vs_mcap!CV6*$B$2+crises_vs_mcap!CW6*$B$3+crises_vs_mcap!CX6*$B$4+crises_vs_mcap!CY6*$B$5+crises_vs_mcap!CZ6*$B$6+crises_vs_mcap!DA6*$B$7) -> 0.037765562
A19: rf | B19: rf_t_10_holdout | C19: monthly | D19: baseline | E19: none | F19: rf_t_10_holdout | G19: =SUM(crises_vs_mcap!J7*$B$2+crises_vs_mcap!K7*$B$3+crises_vs_mcap!L7*$B$4+crises_vs_mcap!M7*$B$5+crises_vs_mcap!N7*$B$6+crises_vs_mcap!O7*$B$7) -> 0.0370207 | H19: =SUM(crises_vs_mcap!P7*$B$2+crises_vs_mcap!Q7*$B$3+crises_vs_mcap!R7*$B$4+crises_vs_mcap!S7*$B$5+crises_vs_mcap!T7*$B$6+crises_vs_mcap!U7*$B$7) -> -0.004439295 | I19: =SUM(crises_vs_mcap!AB7*$B$2+crises_vs_mcap!AC7*$B$3+crises_vs_mcap!AD7*$B$4+crises_vs_mcap!AE7*$B$5+crises_vs_mcap!AF7*$B$6+crises_vs_mcap!AG7*$B$7) -> -0.0022929847 | J19: =(N(crises_vs_mcap!AH7)*$B$2+N(crises_vs_mcap!AI7)*$B$3+N(crises_vs_mcap!AJ7)*$B$4+N(crises_vs_mcap!AK7)*$B$5+N(crises_vs_mcap!AL7)*$B$6+N(crises_vs_mcap!AM7)*$B$7) /(ISNUMBER(crises_vs_mcap!AH7)*$B$2+ISNUMBER(crises_vs_mcap!AI7)*$B$3+ISNUMBER(crises_vs_mcap!AJ7)*$B$4+ISNUMBER(crises_vs_mcap!AK7)*$B$5+ISNUMBER(crises_vs_mcap!AL7)*$B$6+ISNUMBER(crises_vs_mcap!AM7)*$B$7) -> 32.8 | K19: =SUM(crises_vs_mcap!AZ7*$B$2+crises_vs_mcap!BA7*$B$3+crises_vs_mcap!BB7*$B$4+crises_vs_mcap!BC7*$B$5+crises_vs_mcap!BD7*$B$6+crises_vs_mcap!BE7*$B$7) -> -0.013379307 | L19: =SUM(crises_vs_mcap!BL7*$B$2+crises_vs_mcap!BM7*$B$3+crises_vs_mcap!BN7*$B$4+crises_vs_mcap!BO7*$B$5+crises_vs_mcap!BP7*$B$6+crises_vs_mcap!BQ7*$B$7) -> -0.012910783 | M19: =SUM(crises_vs_mcap!BR7*$B$2+crises_vs_mcap!BS7*$B$3+crises_vs_mcap!BT7*$B$4+crises_vs_mcap!BU7*$B$5+crises_vs_mcap!BV7*$B$6+crises_vs_mcap!BW7*$B$7) -> -0.0066408809 | N19: =SUM(crises_vs_mcap!BX7*$B$2+crises_vs_mcap!BY7*$B$3+crises_vs_mcap!BZ7*$B$4+crises_vs_mcap!CA7*$B$5+crises_vs_mcap!CB7*$B$6+crises_vs_mcap!CC7*$B$7) -> -0.5001 | O19: =SUM(crises_vs_mcap!CD7*$B$2+crises_vs_mcap!CE7*$B$3+crises_vs_mcap!CF7*$B$4+crises_vs_mcap!CG7*$B$5+crises_vs_mcap!CH7*$B$6+crises_vs_mcap!CI7*$B$7) -> 0.050657506 | P19: =SUM(crises_vs_mcap!CJ7*$B$2+crises_vs_mcap!CK7*$B$3+crises_vs_mcap!CL7*$B$4+crises_vs_mcap!CM7*$B$5+crises_vs_mcap!CN7*$B$6+crises_vs_mcap!CO7*$B$7) -> -0.016343604 | Q19: =(N(crises_vs_mcap!CP7)*$B$2+N(crises_vs_mcap!CQ7)*$B$3+N(crises_vs_mcap!CR7)*$B$4+N(crises_vs_mcap!CS7)*$B$5+N(crises_vs_mcap!CT7)*$B$6+N(crises_vs_mcap!CU7)*$B$7)/(ISNUMBER(crises_vs_mcap!CP7)*$B$2+ISNUMBER(crises_vs_mcap!CQ7)*$B$3+ISNUMBER(crises_vs_mcap!CR7)*$B$4+ISNUMBER(crises_vs_mcap!CS7)*$B$5+ISNUMBER(crises_vs_mcap!CT7)*$B$6+ISNUMBER(crises_vs_mcap!CU7)*$B$7) -> 44.4 | R19: =SUM(crises_vs_mcap!CV7*$B$2+crises_vs_mcap!CW7*$B$3+crises_vs_mcap!CX7*$B$4+crises_vs_mcap!CY7*$B$5+crises_vs_mcap!CZ7*$B$6+crises_vs_mcap!DA7*$B$7) -> 0.045411043
A20: lstm | B20: lstm_t_10_holdout_rank | C20: monthly | D20: baseline | E20: none | F20: lstm_t_10_holdout_rank | G20: =SUM(crises_vs_mcap!J8*$B$2+crises_vs_mcap!K8*$B$3+crises_vs_mcap!L8*$B$4+crises_vs_mcap!M8*$B$5+crises_vs_mcap!N8*$B$6+crises_vs_mcap!O8*$B$7) -> 0.043965084 | H20: =SUM(crises_vs_mcap!P8*$B$2+crises_vs_mcap!Q8*$B$3+crises_vs_mcap!R8*$B$4+crises_vs_mcap!S8*$B$5+crises_vs_mcap!T8*$B$6+crises_vs_mcap!U8*$B$7) -> 0.00043880703 | I20: =SUM(crises_vs_mcap!AB8*$B$2+crises_vs_mcap!AC8*$B$3+crises_vs_mcap!AD8*$B$4+crises_vs_mcap!AE8*$B$5+crises_vs_mcap!AF8*$B$6+crises_vs_mcap!AG8*$B$7) -> 0.0032476532 | J20: =(N(crises_vs_mcap!AH8)*$B$2+N(crises_vs_mcap!AI8)*$B$3+N(crises_vs_mcap!AJ8)*$B$4+N(crises_vs_mcap!AK8)*$B$5+N(crises_vs_mcap!AL8)*$B$6+N(crises_vs_mcap!AM8)*$B$7) /(ISNUMBER(crises_vs_mcap!AH8)*$B$2+ISNUMBER(crises_vs_mcap!AI8)*$B$3+ISNUMBER(crises_vs_mcap!AJ8)*$B$4+ISNUMBER(crises_vs_mcap!AK8)*$B$5+ISNUMBER(crises_vs_mcap!AL8)*$B$6+ISNUMBER(crises_vs_mcap!AM8)*$B$7) -> 30.6 | K20: =SUM(crises_vs_mcap!AZ8*$B$2+crises_vs_mcap!BA8*$B$3+crises_vs_mcap!BB8*$B$4+crises_vs_mcap!BC8*$B$5+crises_vs_mcap!BD8*$B$6+crises_vs_mcap!BE8*$B$7) -> -0.014010869 | L20: =SUM(crises_vs_mcap!BL8*$B$2+crises_vs_mcap!BM8*$B$3+crises_vs_mcap!BN8*$B$4+crises_vs_mcap!BO8*$B$5+crises_vs_mcap!BP8*$B$6+crises_vs_mcap!BQ8*$B$7) -> -0.0084747571 | M20: =SUM(crises_vs_mcap!BR8*$B$2+crises_vs_mcap!BS8*$B$3+crises_vs_mcap!BT8*$B$4+crises_vs_mcap!BU8*$B$5+crises_vs_mcap!BV8*$B$6+crises_vs_mcap!BW8*$B$7) -> -0.0012534334 | N20: =SUM(crises_vs_mcap!BX8*$B$2+crises_vs_mcap!BY8*$B$3+crises_vs_mcap!BZ8*$B$4+crises_vs_mcap!CA8*$B$5+crises_vs_mcap!CB8*$B$6+crises_vs_mcap!CC8*$B$7) -> 1.8337 | O20: =SUM(crises_vs_mcap!CD8*$B$2+crises_vs_mcap!CE8*$B$3+crises_vs_mcap!CF8*$B$4+crises_vs_mcap!CG8*$B$5+crises_vs_mcap!CH8*$B$6+crises_vs_mcap!CI8*$B$7) -> 0.053866956 | P20: =SUM(crises_vs_mcap!CJ8*$B$2+crises_vs_mcap!CK8*$B$3+crises_vs_mcap!CL8*$B$4+crises_vs_mcap!CM8*$B$5+crises_vs_mcap!CN8*$B$6+crises_vs_mcap!CO8*$B$7) -> -0.015008818 | Q20: =(N(crises_vs_mcap!CP8)*$B$2+N(crises_vs_mcap!CQ8)*$B$3+N(crises_vs_mcap!CR8)*$B$4+N(crises_vs_mcap!CS8)*$B$5+N(crises_vs_mcap!CT8)*$B$6+N(crises_vs_mcap!CU8)*$B$7)/(ISNUMBER(crises_vs_mcap!CP8)*$B$2+ISNUMBER(crises_vs_mcap!CQ8)*$B$3+ISNUMBER(crises_vs_mcap!CR8)*$B$4+ISNUMBER(crises_vs_mcap!CS8)*$B$5+ISNUMBER(crises_vs_mcap!CT8)*$B$6+ISNUMBER(crises_vs_mcap!CU8)*$B$7) -> 39.4 | R20: =SUM(crises_vs_mcap!CV8*$B$2+crises_vs_mcap!CW8*$B$3+crises_vs_mcap!CX8*$B$4+crises_vs_mcap!CY8*$B$5+crises_vs_mcap!CZ8*$B$6+crises_vs_mcap!DA8*$B$7) -> 0.042983653
J22: excluding c1, as mcap did not recover | Q22: excluding c1, as mcap did not recover
A23: Sensitivity Analyses
A24: Drawdown Weighted Crises
A25: model | B25: run | C25: frequency | D25: role | E25: detector | F25: base_run | G25: dd_crisis_exc_ret_full_fix | H25: dd_crisis_exc_dd_full_fix | I25: dd_crisis_exc_dd_full_flex | J25: dd_crisis_exc_days_full_flex | K25: dd_crisis_exc_ulcer_full_flex | L25: dd_crisis_exc_ret_ptt_fix | M25: dd_crisis_exc_dd_ptt_fix | N25: dd_crisis_exc_days_ptt_flex | O25: dd_crisis_exc_ret_ttp_fix | P25: dd_crisis_exc_dd_ttp_fix | Q25: dd_crisis_exc_days_ttp_flex | R25: dd_exc_crisis_ret_to_even_ttp_flex
A26: market_cap | B26: mcap_t_10 | C26: monthly | D26: benchmark | E26: none | G26: =SUM(crises_vs_mcap!J2*$C$2+crises_vs_mcap!K2*$C$3+crises_vs_mcap!L2*$C$4+crises_vs_mcap!M2*$C$5+crises_vs_mcap!N2*$C$6+crises_vs_mcap!O2*$C$7) -> 0 | H26: =SUM(crises_vs_mcap!P2*$C$2+crises_vs_mcap!Q2*$C$3+crises_vs_mcap!R2*$C$4+crises_vs_mcap!S2*$C$5+crises_vs_mcap!T2*$C$6+crises_vs_mcap!U2*$C$7) -> 0 | I26: =SUM(crises_vs_mcap!AB2*$C$2+crises_vs_mcap!AC2*$C$3+crises_vs_mcap!AD2*$C$4+crises_vs_mcap!AE2*$C$5+crises_vs_mcap!AF2*$C$6+crises_vs_mcap!AG2*$C$7) -> 0 | J26: =(N(crises_vs_mcap!AH2)*$C$2+N(crises_vs_mcap!AI2)*$C$3+N(crises_vs_mcap!AJ2)*$C$4+N(crises_vs_mcap!AK2)*$C$5+N(crises_vs_mcap!AL2)*$C$6+N(crises_vs_mcap!AM2)*$C$7)/(ISNUMBER(crises_vs_mcap!AH2)*$C$2+ISNUMBER(crises_vs_mcap!AI2)*$C$3+ISNUMBER(crises_vs_mcap!AJ2)*$C$4+ISNUMBER(crises_vs_mcap!AK2)*$C$5+ISNUMBER(crises_vs_mcap!AL2)*$C$6+ISNUMBER(crises_vs_mcap!AM2)*$C$7) -> 0 | K26: =SUM(crises_vs_mcap!AZ2*$C$2+crises_vs_mcap!BA2*$C$3+crises_vs_mcap!BB2*$C$4+crises_vs_mcap!BC2*$C$5+crises_vs_mcap!BD2*$C$6+crises_vs_mcap!BE2*$B$7) -> 0 | L26: =SUM(crises_vs_mcap!BL2*$C$2+crises_vs_mcap!BM2*$C$3+crises_vs_mcap!BN2*$C$4+crises_vs_mcap!BO2*$C$5+crises_vs_mcap!BP2*$C$6+crises_vs_mcap!BQ2*$C$7) -> 0 | M26: =SUM(crises_vs_mcap!BR2*$C$2+crises_vs_mcap!BS2*$C$3+crises_vs_mcap!BT2*$C$4+crises_vs_mcap!BU2*$C$5+crises_vs_mcap!BV2*$C$6+crises_vs_mcap!BW2*$C$7) -> 0 | N26: =SUM(crises_vs_mcap!BX2*$C$2+crises_vs_mcap!BY2*$C$3+crises_vs_mcap!BZ2*$C$4+crises_vs_mcap!CA2*$C$5+crises_vs_mcap!CB2*$C$6+crises_vs_mcap!CC2*$C$7) -> 0 | O26: =SUM(crises_vs_mcap!CD2*$C$2+crises_vs_mcap!CE2*$C$3+crises_vs_mcap!CF2*$C$4+crises_vs_mcap!CG2*$C$5+crises_vs_mcap!CH2*$C$6+crises_vs_mcap!CI2*$C$7) -> 0 | P26: =SUM(crises_vs_mcap!CJ2*$C$2+crises_vs_mcap!CK2*$C$3+crises_vs_mcap!CL2*$C$4+crises_vs_mcap!CM2*$C$5+crises_vs_mcap!CN2*$C$6+crises_vs_mcap!CO2*$C$7) -> 0 | Q26: =(N(crises_vs_mcap!CP2)*$C$2+N(crises_vs_mcap!CQ2)*$C$3+N(crises_vs_mcap!CR2)*$C$4+N(crises_vs_mcap!CS2)*$C$5+N(crises_vs_mcap!CT2)*$C$6+N(crises_vs_mcap!CU2)*$C$7)/(ISNUMBER(crises_vs_mcap!CP2)*$C$2+ISNUMBER(crises_vs_mcap!CQ2)*$C$3+ISNUMBER(crises_vs_mcap!CR2)*$C$4+ISNUMBER(crises_vs_mcap!CS2)*$C$5+ISNUMBER(crises_vs_mcap!CT2)*$C$6+ISNUMBER(crises_vs_mcap!CU2)*$C$7) -> 0 | R26: =SUM(crises_vs_mcap!CV2*$C$2+crises_vs_mcap!CW2*$C$3+crises_vs_mcap!CX2*$C$4+crises_vs_mcap!CY2*$C$5+crises_vs_mcap!CZ2*$C$6+crises_vs_mcap!DA2*$C$7) -> 0
A27: equal_weight | B27: equal_t_10 | C27: monthly | D27: baseline | E27: none | F27: equal_t_10 | G27: =SUM(crises_vs_mcap!J3*$C$2+crises_vs_mcap!K3*$C$3+crises_vs_mcap!L3*$C$4+crises_vs_mcap!M3*$C$5+crises_vs_mcap!N3*$C$6+crises_vs_mcap!O3*$C$7) -> 0.042692106 | H27: =SUM(crises_vs_mcap!P3*$C$2+crises_vs_mcap!Q3*$C$3+crises_vs_mcap!R3*$C$4+crises_vs_mcap!S3*$C$5+crises_vs_mcap!T3*$C$6+crises_vs_mcap!U3*$C$7) -> 0.015989393 | I27: =SUM(crises_vs_mcap!AB3*$C$2+crises_vs_mcap!AC3*$C$3+crises_vs_mcap!AD3*$C$4+crises_vs_mcap!AE3*$C$5+crises_vs_mcap!AF3*$C$6+crises_vs_mcap!AG3*$C$7) -> 0.020072673 | J27: =(N(crises_vs_mcap!AH3)*$C$2+N(crises_vs_mcap!AI3)*$C$3+N(crises_vs_mcap!AJ3)*$C$4+N(crises_vs_mcap!AK3)*$C$5+N(crises_vs_mcap!AL3)*$C$6+N(crises_vs_mcap!AM3)*$C$7)/(ISNUMBER(crises_vs_mcap!AH3)*$C$2+ISNUMBER(crises_vs_mcap!AI3)*$C$3+ISNUMBER(crises_vs_mcap!AJ3)*$C$4+ISNUMBER(crises_vs_mcap!AK3)*$C$5+ISNUMBER(crises_vs_mcap!AL3)*$C$6+ISNUMBER(crises_vs_mcap!AM3)*$C$7) -> 42.221373 | K27: =SUM(crises_vs_mcap!AZ3*$C$2+crises_vs_mcap!BA3*$C$3+crises_vs_mcap!BB3*$C$4+crises_vs_mcap!BC3*$C$5+crises_vs_mcap!BD3*$C$6+crises_vs_mcap!BE3*$B$7) -> -0.027414331 | L27: =SUM(crises_vs_mcap!BL3*$C$2+crises_vs_mcap!BM3*$C$3+crises_vs_mcap!BN3*$C$4+crises_vs_mcap!BO3*$C$5+crises_vs_mcap!BP3*$C$6+crises_vs_mcap!BQ3*$C$7) -> 0.025335285 | M27: =SUM(crises_vs_mcap!BR3*$C$2+crises_vs_mcap!BS3*$C$3+crises_vs_mcap!BT3*$C$4+crises_vs_mcap!BU3*$C$5+crises_vs_mcap!BV3*$C$6+crises_vs_mcap!BW3*$C$7) -> 0.01422744 | N27: =SUM(crises_vs_mcap!BX3*$C$2+crises_vs_mcap!BY3*$C$3+crises_vs_mcap!BZ3*$C$4+crises_vs_mcap!CA3*$C$5+crises_vs_mcap!CB3*$C$6+crises_vs_mcap!CC3*$C$7) -> -7.2326 | O27: =SUM(crises_vs_mcap!CD3*$C$2+crises_vs_mcap!CE3*$C$3+crises_vs_mcap!CF3*$C$4+crises_vs_mcap!CG3*$C$5+crises_vs_mcap!CH3*$C$6+crises_vs_mcap!CI3*$C$7) -> 0.017744519 | P27: =SUM(crises_vs_mcap!CJ3*$C$2+crises_vs_mcap!CK3*$C$3+crises_vs_mcap!CL3*$C$4+crises_vs_mcap!CM3*$C$5+crises_vs_mcap!CN3*$C$6+crises_vs_mcap!CO3*$C$7) -> -0.003133205 | Q27: =(N(crises_vs_mcap!CP3)*$C$2+N(crises_vs_mcap!CQ3)*$C$3+N(crises_vs_mcap!CR3)*$C$4+N(crises_vs_mcap!CS3)*$C$5+N(crises_vs_mcap!CT3)*$C$6+N(crises_vs_mcap!CU3)*$C$7)/(ISNUMBER(crises_vs_mcap!CP3)*$C$2+ISNUMBER(crises_vs_mcap!CQ3)*$C$3+ISNUMBER(crises_vs_mcap!CR3)*$C$4+ISNUMBER(crises_vs_mcap!CS3)*$C$5+ISNUMBER(crises_vs_mcap!CT3)*$C$6+ISNUMBER(crises_vs_mcap!CU3)*$C$7) -> 51.751746 | R27: =SUM(crises_vs_mcap!CV3*$C$2+crises_vs_mcap!CW3*$C$3+crises_vs_mcap!CX3*$C$4+crises_vs_mcap!CY3*$C$5+crises_vs_mcap!CZ3*$C$6+crises_vs_mcap!DA3*$C$7) -> -0.030365979
A28: mvo | B28: mvo_t_10_lw | C28: monthly | D28: baseline | E28: none | F28: mvo_t_10_lw | G28: =SUM(crises_vs_mcap!J4*$C$2+crises_vs_mcap!K4*$C$3+crises_vs_mcap!L4*$C$4+crises_vs_mcap!M4*$C$5+crises_vs_mcap!N4*$C$6+crises_vs_mcap!O4*$C$7) -> 0.029232965 | H28: =SUM(crises_vs_mcap!P4*$C$2+crises_vs_mcap!Q4*$C$3+crises_vs_mcap!R4*$C$4+crises_vs_mcap!S4*$C$5+crises_vs_mcap!T4*$C$6+crises_vs_mcap!U4*$C$7) -> 0.0068491679 | I28: =SUM(crises_vs_mcap!AB4*$C$2+crises_vs_mcap!AC4*$C$3+crises_vs_mcap!AD4*$C$4+crises_vs_mcap!AE4*$C$5+crises_vs_mcap!AF4*$C$6+crises_vs_mcap!AG4*$C$7) -> 0.0096963522 | J28: =(N(crises_vs_mcap!AH4)*$C$2+N(crises_vs_mcap!AI4)*$C$3+N(crises_vs_mcap!AJ4)*$C$4+N(crises_vs_mcap!AK4)*$C$5+N(crises_vs_mcap!AL4)*$C$6+N(crises_vs_mcap!AM4)*$C$7)/(ISNUMBER(crises_vs_mcap!AH4)*$C$2+ISNUMBER(crises_vs_mcap!AI4)*$C$3+ISNUMBER(crises_vs_mcap!AJ4)*$C$4+ISNUMBER(crises_vs_mcap!AK4)*$C$5+ISNUMBER(crises_vs_mcap!AL4)*$C$6+ISNUMBER(crises_vs_mcap!AM4)*$C$7) -> -144.34181 | K28: =SUM(crises_vs_mcap!AZ4*$C$2+crises_vs_mcap!BA4*$C$3+crises_vs_mcap!BB4*$C$4+crises_vs_mcap!BC4*$C$5+crises_vs_mcap!BD4*$C$6+crises_vs_mcap!BE4*$B$7) -> 0.0026449416 | L28: =SUM(crises_vs_mcap!BL4*$C$2+crises_vs_mcap!BM4*$C$3+crises_vs_mcap!BN4*$C$4+crises_vs_mcap!BO4*$C$5+crises_vs_mcap!BP4*$C$6+crises_vs_mcap!BQ4*$C$7) -> 0.016675301 | M28: =SUM(crises_vs_mcap!BR4*$C$2+crises_vs_mcap!BS4*$C$3+crises_vs_mcap!BT4*$C$4+crises_vs_mcap!BU4*$C$5+crises_vs_mcap!BV4*$C$6+crises_vs_mcap!BW4*$C$7) -> 0.0055623667 | N28: =SUM(crises_vs_mcap!BX4*$C$2+crises_vs_mcap!BY4*$C$3+crises_vs_mcap!BZ4*$C$4+crises_vs_mcap!CA4*$C$5+crises_vs_mcap!CB4*$C$6+crises_vs_mcap!CC4*$C$7) -> -0.1854 | O28: =SUM(crises_vs_mcap!CD4*$C$2+crises_vs_mcap!CE4*$C$3+crises_vs_mcap!CF4*$C$4+crises_vs_mcap!CG4*$C$5+crises_vs_mcap!CH4*$C$6+crises_vs_mcap!CI4*$C$7) -> 0.011741386 | P28: =SUM(crises_vs_mcap!CJ4*$C$2+crises_vs_mcap!CK4*$C$3+crises_vs_mcap!CL4*$C$4+crises_vs_mcap!CM4*$C$5+crises_vs_mcap!CN4*$C$6+crises_vs_mcap!CO4*$C$7) -> 0.0095953269 | Q28: =(N(crises_vs_mcap!CP4)*$C$2+N(crises_vs_mcap!CQ4)*$C$3+N(crises_vs_mcap!CR4)*$C$4+N(crises_vs_mcap!CS4)*$C$5+N(crises_vs_mcap!CT4)*$C$6+N(crises_vs_mcap!CU4)*$C$7)/(ISNUMBER(crises_vs_mcap!CP4)*$C$2+ISNUMBER(crises_vs_mcap!CQ4)*$C$3+ISNUMBER(crises_vs_mcap!CR4)*$C$4+ISNUMBER(crises_vs_mcap!CS4)*$C$5+ISNUMBER(crises_vs_mcap!CT4)*$C$6+ISNUMBER(crises_vs_mcap!CU4)*$C$7) -> -144.09751 | R28: =SUM(crises_vs_mcap!CV4*$C$2+crises_vs_mcap!CW4*$C$3+crises_vs_mcap!CX4*$C$4+crises_vs_mcap!CY4*$C$5+crises_vs_mcap!CZ4*$C$6+crises_vs_mcap!DA4*$C$7) -> -0.021460093
A29: hrp | B29: hrp_t_10_lw_ward | C29: monthly | D29: baseline | E29: none | F29: hrp_t_10_lw_ward | G29: =SUM(crises_vs_mcap!J5*$C$2+crises_vs_mcap!K5*$C$3+crises_vs_mcap!L5*$C$4+crises_vs_mcap!M5*$C$5+crises_vs_mcap!N5*$C$6+crises_vs_mcap!O5*$C$7) -> 0.13876743 | H29: =SUM(crises_vs_mcap!P5*$C$2+crises_vs_mcap!Q5*$C$3+crises_vs_mcap!R5*$C$4+crises_vs_mcap!S5*$C$5+crises_vs_mcap!T5*$C$6+crises_vs_mcap!U5*$C$7) -> 0.069947225 | I29: =SUM(crises_vs_mcap!AB5*$C$2+crises_vs_mcap!AC5*$C$3+crises_vs_mcap!AD5*$C$4+crises_vs_mcap!AE5*$C$5+crises_vs_mcap!AF5*$C$6+crises_vs_mcap!AG5*$C$7) -> 0.079031464 | J29: =(N(crises_vs_mcap!AH5)*$C$2+N(crises_vs_mcap!AI5)*$C$3+N(crises_vs_mcap!AJ5)*$C$4+N(crises_vs_mcap!AK5)*$C$5+N(crises_vs_mcap!AL5)*$C$6+N(crises_vs_mcap!AM5)*$C$7)/(ISNUMBER(crises_vs_mcap!AH5)*$C$2+ISNUMBER(crises_vs_mcap!AI5)*$C$3+ISNUMBER(crises_vs_mcap!AJ5)*$C$4+ISNUMBER(crises_vs_mcap!AK5)*$C$5+ISNUMBER(crises_vs_mcap!AL5)*$C$6+ISNUMBER(crises_vs_mcap!AM5)*$C$7) -> -53.347608 | K29: =SUM(crises_vs_mcap!AZ5*$C$2+crises_vs_mcap!BA5*$C$3+crises_vs_mcap!BB5*$C$4+crises_vs_mcap!BC5*$C$5+crises_vs_mcap!BD5*$C$6+crises_vs_mcap!BE5*$B$7) -> -0.058826081 | L29: =SUM(crises_vs_mcap!BL5*$C$2+crises_vs_mcap!BM5*$C$3+crises_vs_mcap!BN5*$C$4+crises_vs_mcap!BO5*$C$5+crises_vs_mcap!BP5*$C$6+crises_vs_mcap!BQ5*$C$7) -> 0.1480276 | M29: =SUM(crises_vs_mcap!BR5*$C$2+crises_vs_mcap!BS5*$C$3+crises_vs_mcap!BT5*$C$4+crises_vs_mcap!BU5*$C$5+crises_vs_mcap!BV5*$C$6+crises_vs_mcap!BW5*$C$7) -> 0.068185272 | N29: =SUM(crises_vs_mcap!BX5*$C$2+crises_vs_mcap!BY5*$C$3+crises_vs_mcap!BZ5*$C$4+crises_vs_mcap!CA5*$C$5+crises_vs_mcap!CB5*$C$6+crises_vs_mcap!CC5*$C$7) -> -7.2326 | O29: =SUM(crises_vs_mcap!CD5*$C$2+crises_vs_mcap!CE5*$C$3+crises_vs_mcap!CF5*$C$4+crises_vs_mcap!CG5*$C$5+crises_vs_mcap!CH5*$C$6+crises_vs_mcap!CI5*$C$7) -> -0.012074265 | P29: =SUM(crises_vs_mcap!CJ5*$C$2+crises_vs_mcap!CK5*$C$3+crises_vs_mcap!CL5*$C$4+crises_vs_mcap!CM5*$C$5+crises_vs_mcap!CN5*$C$6+crises_vs_mcap!CO5*$C$7) -> 0.016532668 | Q29: =(N(crises_vs_mcap!CP5)*$C$2+N(crises_vs_mcap!CQ5)*$C$3+N(crises_vs_mcap!CR5)*$C$4+N(crises_vs_mcap!CS5)*$C$5+N(crises_vs_mcap!CT5)*$C$6+N(crises_vs_mcap!CU5)*$C$7)/(ISNUMBER(crises_vs_mcap!CP5)*$C$2+ISNUMBER(crises_vs_mcap!CQ5)*$C$3+ISNUMBER(crises_vs_mcap!CR5)*$C$4+ISNUMBER(crises_vs_mcap!CS5)*$C$5+ISNUMBER(crises_vs_mcap!CT5)*$C$6+ISNUMBER(crises_vs_mcap!CU5)*$C$7) -> -43.817235 | R29: =SUM(crises_vs_mcap!CV5*$C$2+crises_vs_mcap!CW5*$C$3+crises_vs_mcap!CX5*$C$4+crises_vs_mcap!CY5*$C$5+crises_vs_mcap!CZ5*$C$6+crises_vs_mcap!DA5*$C$7) -> -0.20882591
A30: xgb | B30: xgb_t_10_holdout | C30: monthly | D30: baseline | E30: none | F30: xgb_t_10_holdout | G30: =SUM(crises_vs_mcap!J6*$C$2+crises_vs_mcap!K6*$C$3+crises_vs_mcap!L6*$C$4+crises_vs_mcap!M6*$C$5+crises_vs_mcap!N6*$C$6+crises_vs_mcap!O6*$C$7) -> 0.041469451 | H30: =SUM(crises_vs_mcap!P6*$C$2+crises_vs_mcap!Q6*$C$3+crises_vs_mcap!R6*$C$4+crises_vs_mcap!S6*$C$5+crises_vs_mcap!T6*$C$6+crises_vs_mcap!U6*$C$7) -> -0.0074922429 | I30: =SUM(crises_vs_mcap!AB6*$C$2+crises_vs_mcap!AC6*$C$3+crises_vs_mcap!AD6*$C$4+crises_vs_mcap!AE6*$C$5+crises_vs_mcap!AF6*$C$6+crises_vs_mcap!AG6*$C$7) -> -0.0042729429 | J30: =(N(crises_vs_mcap!AH6)*$C$2+N(crises_vs_mcap!AI6)*$C$3+N(crises_vs_mcap!AJ6)*$C$4+N(crises_vs_mcap!AK6)*$C$5+N(crises_vs_mcap!AL6)*$C$6+N(crises_vs_mcap!AM6)*$C$7)/(ISNUMBER(crises_vs_mcap!AH6)*$C$2+ISNUMBER(crises_vs_mcap!AI6)*$C$3+ISNUMBER(crises_vs_mcap!AJ6)*$C$4+ISNUMBER(crises_vs_mcap!AK6)*$C$5+ISNUMBER(crises_vs_mcap!AL6)*$C$6+ISNUMBER(crises_vs_mcap!AM6)*$C$7) -> 58.082751 | K30: =SUM(crises_vs_mcap!AZ6*$C$2+crises_vs_mcap!BA6*$C$3+crises_vs_mcap!BB6*$C$4+crises_vs_mcap!BC6*$C$5+crises_vs_mcap!BD6*$C$6+crises_vs_mcap!BE6*$B$7) -> -0.020422222 | L30: =SUM(crises_vs_mcap!BL6*$C$2+crises_vs_mcap!BM6*$C$3+crises_vs_mcap!BN6*$C$4+crises_vs_mcap!BO6*$C$5+crises_vs_mcap!BP6*$C$6+crises_vs_mcap!BQ6*$C$7) -> -0.020118102 | M30: =SUM(crises_vs_mcap!BR6*$C$2+crises_vs_mcap!BS6*$C$3+crises_vs_mcap!BT6*$C$4+crises_vs_mcap!BU6*$C$5+crises_vs_mcap!BV6*$C$6+crises_vs_mcap!BW6*$C$7) -> -0.0092019189 | N30: =SUM(crises_vs_mcap!BX6*$C$2+crises_vs_mcap!BY6*$C$3+crises_vs_mcap!BZ6*$C$4+crises_vs_mcap!CA6*$C$5+crises_vs_mcap!CB6*$C$6+crises_vs_mcap!CC6*$C$7) -> 5.715 | O30: =SUM(crises_vs_mcap!CD6*$C$2+crises_vs_mcap!CE6*$C$3+crises_vs_mcap!CF6*$C$4+crises_vs_mcap!CG6*$C$5+crises_vs_mcap!CH6*$C$6+crises_vs_mcap!CI6*$C$7) -> 0.068987253 | P30: =SUM(crises_vs_mcap!CJ6*$C$2+crises_vs_mcap!CK6*$C$3+crises_vs_mcap!CL6*$C$4+crises_vs_mcap!CM6*$C$5+crises_vs_mcap!CN6*$C$6+crises_vs_mcap!CO6*$C$7) -> -0.019147665 | Q30: =(N(crises_vs_mcap!CP6)*$C$2+N(crises_vs_mcap!CQ6)*$C$3+N(crises_vs_mcap!CR6)*$C$4+N(crises_vs_mcap!CS6)*$C$5+N(crises_vs_mcap!CT6)*$C$6+N(crises_vs_mcap!CU6)*$C$7)/(ISNUMBER(crises_vs_mcap!CP6)*$C$2+ISNUMBER(crises_vs_mcap!CQ6)*$C$3+ISNUMBER(crises_vs_mcap!CR6)*$C$4+ISNUMBER(crises_vs_mcap!CS6)*$C$5+ISNUMBER(crises_vs_mcap!CT6)*$C$6+ISNUMBER(crises_vs_mcap!CU6)*$C$7) -> 68.018184 | R30: =SUM(crises_vs_mcap!CV6*$C$2+crises_vs_mcap!CW6*$C$3+crises_vs_mcap!CX6*$C$4+crises_vs_mcap!CY6*$C$5+crises_vs_mcap!CZ6*$C$6+crises_vs_mcap!DA6*$C$7) -> 0.0819113
A31: rf | B31: rf_t_10_holdout | C31: monthly | D31: baseline | E31: none | F31: rf_t_10_holdout | G31: =SUM(crises_vs_mcap!J7*$C$2+crises_vs_mcap!K7*$C$3+crises_vs_mcap!L7*$C$4+crises_vs_mcap!M7*$C$5+crises_vs_mcap!N7*$C$6+crises_vs_mcap!O7*$C$7) -> 0.043651542 | H31: =SUM(crises_vs_mcap!P7*$C$2+crises_vs_mcap!Q7*$C$3+crises_vs_mcap!R7*$C$4+crises_vs_mcap!S7*$C$5+crises_vs_mcap!T7*$C$6+crises_vs_mcap!U7*$C$7) -> -0.012838134 | I31: =SUM(crises_vs_mcap!AB7*$C$2+crises_vs_mcap!AC7*$C$3+crises_vs_mcap!AD7*$C$4+crises_vs_mcap!AE7*$C$5+crises_vs_mcap!AF7*$C$6+crises_vs_mcap!AG7*$C$7) -> -0.0087925175 | J31: =(N(crises_vs_mcap!AH7)*$C$2+N(crises_vs_mcap!AI7)*$C$3+N(crises_vs_mcap!AJ7)*$C$4+N(crises_vs_mcap!AK7)*$C$5+N(crises_vs_mcap!AL7)*$C$6+N(crises_vs_mcap!AM7)*$C$7)/(ISNUMBER(crises_vs_mcap!AH7)*$C$2+ISNUMBER(crises_vs_mcap!AI7)*$C$3+ISNUMBER(crises_vs_mcap!AJ7)*$C$4+ISNUMBER(crises_vs_mcap!AK7)*$C$5+ISNUMBER(crises_vs_mcap!AL7)*$C$6+ISNUMBER(crises_vs_mcap!AM7)*$C$7) -> 79.761365 | K31: =SUM(crises_vs_mcap!AZ7*$C$2+crises_vs_mcap!BA7*$C$3+crises_vs_mcap!BB7*$C$4+crises_vs_mcap!BC7*$C$5+crises_vs_mcap!BD7*$C$6+crises_vs_mcap!BE7*$B$7) -> -0.01589831 | L31: =SUM(crises_vs_mcap!BL7*$C$2+crises_vs_mcap!BM7*$C$3+crises_vs_mcap!BN7*$C$4+crises_vs_mcap!BO7*$C$5+crises_vs_mcap!BP7*$C$6+crises_vs_mcap!BQ7*$C$7) -> -0.025202137 | M31: =SUM(crises_vs_mcap!BR7*$C$2+crises_vs_mcap!BS7*$C$3+crises_vs_mcap!BT7*$C$4+crises_vs_mcap!BU7*$C$5+crises_vs_mcap!BV7*$C$6+crises_vs_mcap!BW7*$C$7) -> -0.014485031 | N31: =SUM(crises_vs_mcap!BX7*$C$2+crises_vs_mcap!BY7*$C$3+crises_vs_mcap!BZ7*$C$4+crises_vs_mcap!CA7*$C$5+crises_vs_mcap!CB7*$C$6+crises_vs_mcap!CC7*$C$7) -> 5.715 | O31: =SUM(crises_vs_mcap!CD7*$C$2+crises_vs_mcap!CE7*$C$3+crises_vs_mcap!CF7*$C$4+crises_vs_mcap!CG7*$C$5+crises_vs_mcap!CH7*$C$6+crises_vs_mcap!CI7*$C$7) -> 0.070482728 | P31: =SUM(crises_vs_mcap!CJ7*$C$2+crises_vs_mcap!CK7*$C$3+crises_vs_mcap!CL7*$C$4+crises_vs_mcap!CM7*$C$5+crises_vs_mcap!CN7*$C$6+crises_vs_mcap!CO7*$C$7) -> -0.020228077 | Q31: =(N(crises_vs_mcap!CP7)*$C$2+N(crises_vs_mcap!CQ7)*$C$3+N(crises_vs_mcap!CR7)*$C$4+N(crises_vs_mcap!CS7)*$C$5+N(crises_vs_mcap!CT7)*$C$6+N(crises_vs_mcap!CU7)*$C$7)/(ISNUMBER(crises_vs_mcap!CP7)*$C$2+ISNUMBER(crises_vs_mcap!CQ7)*$C$3+ISNUMBER(crises_vs_mcap!CR7)*$C$4+ISNUMBER(crises_vs_mcap!CS7)*$C$5+ISNUMBER(crises_vs_mcap!CT7)*$C$6+ISNUMBER(crises_vs_mcap!CU7)*$C$7) -> 89.696798 | R31: =SUM(crises_vs_mcap!CV7*$C$2+crises_vs_mcap!CW7*$C$3+crises_vs_mcap!CX7*$C$4+crises_vs_mcap!CY7*$C$5+crises_vs_mcap!CZ7*$C$6+crises_vs_mcap!DA7*$C$7) -> 0.085267952
A32: lstm | B32: lstm_t_10_holdout_rank | C32: monthly | D32: baseline | E32: none | F32: lstm_t_10_holdout_rank | G32: =SUM(crises_vs_mcap!J8*$C$2+crises_vs_mcap!K8*$C$3+crises_vs_mcap!L8*$C$4+crises_vs_mcap!M8*$C$5+crises_vs_mcap!N8*$C$6+crises_vs_mcap!O8*$C$7) -> 0.050647037 | H32: =SUM(crises_vs_mcap!P8*$C$2+crises_vs_mcap!Q8*$C$3+crises_vs_mcap!R8*$C$4+crises_vs_mcap!S8*$C$5+crises_vs_mcap!T8*$C$6+crises_vs_mcap!U8*$C$7) -> -0.01332849 | I32: =SUM(crises_vs_mcap!AB8*$C$2+crises_vs_mcap!AC8*$C$3+crises_vs_mcap!AD8*$C$4+crises_vs_mcap!AE8*$C$5+crises_vs_mcap!AF8*$C$6+crises_vs_mcap!AG8*$C$7) -> -0.0082967802 | J32: =(N(crises_vs_mcap!AH8)*$C$2+N(crises_vs_mcap!AI8)*$C$3+N(crises_vs_mcap!AJ8)*$C$4+N(crises_vs_mcap!AK8)*$C$5+N(crises_vs_mcap!AL8)*$C$6+N(crises_vs_mcap!AM8)*$C$7)/(ISNUMBER(crises_vs_mcap!AH8)*$C$2+ISNUMBER(crises_vs_mcap!AI8)*$C$3+ISNUMBER(crises_vs_mcap!AJ8)*$C$4+ISNUMBER(crises_vs_mcap!AK8)*$C$5+ISNUMBER(crises_vs_mcap!AL8)*$C$6+ISNUMBER(crises_vs_mcap!AM8)*$C$7) -> 77.768481 | K32: =SUM(crises_vs_mcap!AZ8*$C$2+crises_vs_mcap!BA8*$C$3+crises_vs_mcap!BB8*$C$4+crises_vs_mcap!BC8*$C$5+crises_vs_mcap!BD8*$C$6+crises_vs_mcap!BE8*$B$7) -> -0.014076607 | L32: =SUM(crises_vs_mcap!BL8*$C$2+crises_vs_mcap!BM8*$C$3+crises_vs_mcap!BN8*$C$4+crises_vs_mcap!BO8*$C$5+crises_vs_mcap!BP8*$C$6+crises_vs_mcap!BQ8*$C$7) -> -0.029424819 | M32: =SUM(crises_vs_mcap!BR8*$C$2+crises_vs_mcap!BS8*$C$3+crises_vs_mcap!BT8*$C$4+crises_vs_mcap!BU8*$C$5+crises_vs_mcap!BV8*$C$6+crises_vs_mcap!BW8*$C$7) -> -0.014594371 | N32: =SUM(crises_vs_mcap!BX8*$C$2+crises_vs_mcap!BY8*$C$3+crises_vs_mcap!BZ8*$C$4+crises_vs_mcap!CA8*$C$5+crises_vs_mcap!CB8*$C$6+crises_vs_mcap!CC8*$C$7) -> 7.4608 | O32: =SUM(crises_vs_mcap!CD8*$C$2+crises_vs_mcap!CE8*$C$3+crises_vs_mcap!CF8*$C$4+crises_vs_mcap!CG8*$C$5+crises_vs_mcap!CH8*$C$6+crises_vs_mcap!CI8*$C$7) -> 0.081900476 | P32: =SUM(crises_vs_mcap!CJ8*$C$2+crises_vs_mcap!CK8*$C$3+crises_vs_mcap!CL8*$C$4+crises_vs_mcap!CM8*$C$5+crises_vs_mcap!CN8*$C$6+crises_vs_mcap!CO8*$C$7) -> -0.020787331 | Q32: =(N(crises_vs_mcap!CP8)*$C$2+N(crises_vs_mcap!CQ8)*$C$3+N(crises_vs_mcap!CR8)*$C$4+N(crises_vs_mcap!CS8)*$C$5+N(crises_vs_mcap!CT8)*$C$6+N(crises_vs_mcap!CU8)*$C$7)/(ISNUMBER(crises_vs_mcap!CP8)*$C$2+ISNUMBER(crises_vs_mcap!CQ8)*$C$3+ISNUMBER(crises_vs_mcap!CR8)*$C$4+ISNUMBER(crises_vs_mcap!CS8)*$C$5+ISNUMBER(crises_vs_mcap!CT8)*$C$6+ISNUMBER(crises_vs_mcap!CU8)*$C$7) -> 85.403479 | R32: =SUM(crises_vs_mcap!CV8*$C$2+crises_vs_mcap!CW8*$C$3+crises_vs_mcap!CX8*$C$4+crises_vs_mcap!CY8*$C$5+crises_vs_mcap!CZ8*$C$6+crises_vs_mcap!DA8*$C$7) -> 0.094958364
A34: Duration Weighted Crises
A35: model | B35: run | C35: frequency | D35: role | E35: detector | F35: base_run | G35: dur_crisis_exc_ret_full_fix | H35: dur_crisis_exc_dd_full_fix | I35: dur_crisis_exc_dd_full_flex | J35: dur_crisis_exc_days_full_flex | K35: dur_crisis_exc_ulcer_full_flex | L35: dur_crisis_exc_ret_ptt_fix | M35: dur_crisis_exc_dd_ptt_fix | N35: dur_crisis_exc_days_ptt_flex | O35: dur_crisis_exc_ret_ttp_fix | P35: dur_crisis_exc_dd_ttp_fix | Q35: dur_crisis_exc_days_ttp_flex | R35: dur_exc_crisis_ret_to_even_ttp_flex
A36: market_cap | B36: mcap_t_10 | C36: monthly | D36: benchmark | E36: none | G36: =SUM(crises_vs_mcap!J2*$D$2+crises_vs_mcap!K2*$D$3+crises_vs_mcap!L2*$D$4+crises_vs_mcap!M2*$D$5+crises_vs_mcap!N2*$D$6+crises_vs_mcap!O2*$D$7) -> 0 | H36: =SUM(crises_vs_mcap!P2*$D$2+crises_vs_mcap!Q2*$D$3+crises_vs_mcap!R2*$D$4+crises_vs_mcap!S2*$D$5+crises_vs_mcap!T2*$D$6+crises_vs_mcap!U2*$D$7) -> 0 | I36: =SUM(crises_vs_mcap!AB2*$D$2+crises_vs_mcap!AC2*$D$3+crises_vs_mcap!AD2*$D$4+crises_vs_mcap!AE2*$D$5+crises_vs_mcap!AF2*$D$6+crises_vs_mcap!AG2*$D$7) -> 0 | J36: =(N(crises_vs_mcap!AH2)*$D$2+N(crises_vs_mcap!AI2)*$D$3+N(crises_vs_mcap!AJ2)*$D$4+N(crises_vs_mcap!AK2)*$D$5+N(crises_vs_mcap!AL2)*$D$6+N(crises_vs_mcap!AM2)*$D$7)/(ISNUMBER(crises_vs_mcap!AH2)*$D$2+ISNUMBER(crises_vs_mcap!AI2)*$D$3+ISNUMBER(crises_vs_mcap!AJ2)*$D$4+ISNUMBER(crises_vs_mcap!AK2)*$D$5+ISNUMBER(crises_vs_mcap!AL2)*$D$6+ISNUMBER(crises_vs_mcap!AM2)*$D$7) -> 0 | K36: =SUM(crises_vs_mcap!AZ2*$D$2+crises_vs_mcap!BA2*$D$3+crises_vs_mcap!BB2*$D$4+crises_vs_mcap!BC2*$D$5+crises_vs_mcap!BD2*$D$6+crises_vs_mcap!BE2*$D$7) -> 0 | L36: =SUM(crises_vs_mcap!BL2*$D$2+crises_vs_mcap!BM2*$D$3+crises_vs_mcap!BN2*$D$4+crises_vs_mcap!BO2*$D$5+crises_vs_mcap!BP2*$D$6+crises_vs_mcap!BQ2*$D$7) -> 0 | M36: =SUM(crises_vs_mcap!BR2*$D$2+crises_vs_mcap!BS2*$D$3+crises_vs_mcap!BT2*$D$4+crises_vs_mcap!BU2*$D$5+crises_vs_mcap!BV2*$D$6+crises_vs_mcap!BW2*$D$7) -> 0 | N36: =SUM(crises_vs_mcap!BX2*$D$2+crises_vs_mcap!BY2*$D$3+crises_vs_mcap!BZ2*$D$4+crises_vs_mcap!CA2*$D$5+crises_vs_mcap!CB2*$D$6+crises_vs_mcap!CC2*$D$7) -> 0 | O36: =SUM(crises_vs_mcap!CD2*$D$2+crises_vs_mcap!CE2*$D$3+crises_vs_mcap!CF2*$D$4+crises_vs_mcap!CG2*$D$5+crises_vs_mcap!CH2*$D$6+crises_vs_mcap!CI2*$D$7) -> 0 | P36: =SUM(crises_vs_mcap!CJ2*$D$2+crises_vs_mcap!CK2*$D$3+crises_vs_mcap!CL2*$D$4+crises_vs_mcap!CM2*$D$5+crises_vs_mcap!CN2*$D$6+crises_vs_mcap!CO2*$D$7) -> 0 | Q36: =(N(crises_vs_mcap!CP2)*$D$2+N(crises_vs_mcap!CQ2)*$D$3+N(crises_vs_mcap!CR2)*$D$4+N(crises_vs_mcap!CS2)*$D$5+N(crises_vs_mcap!CT2)*$D$6+N(crises_vs_mcap!CU2)*$D$7)/(ISNUMBER(crises_vs_mcap!CP2)*$D$2+ISNUMBER(crises_vs_mcap!CQ2)*$D$3+ISNUMBER(crises_vs_mcap!CR2)*$D$4+ISNUMBER(crises_vs_mcap!CS2)*$D$5+ISNUMBER(crises_vs_mcap!CT2)*$D$6+ISNUMBER(crises_vs_mcap!CU2)*$D$7) -> 0 | R36: =SUM(crises_vs_mcap!CV2*$D$2+crises_vs_mcap!CW2*$D$3+crises_vs_mcap!CX2*$D$4+crises_vs_mcap!CY2*$D$5+crises_vs_mcap!CZ2*$D$6+crises_vs_mcap!DA2*$D$7) -> 0
A37: equal_weight | B37: equal_t_10 | C37: monthly | D37: baseline | E37: none | F37: equal_t_10 | G37: =SUM(crises_vs_mcap!J3*$D$2+crises_vs_mcap!K3*$D$3+crises_vs_mcap!L3*$D$4+crises_vs_mcap!M3*$D$5+crises_vs_mcap!N3*$D$6+crises_vs_mcap!O3*$D$7) -> 0.1191734 | H37: =SUM(crises_vs_mcap!P3*$D$2+crises_vs_mcap!Q3*$D$3+crises_vs_mcap!R3*$D$4+crises_vs_mcap!S3*$D$5+crises_vs_mcap!T3*$D$6+crises_vs_mcap!U3*$D$7) -> 0.038697397 | I37: =SUM(crises_vs_mcap!AB3*$D$2+crises_vs_mcap!AC3*$D$3+crises_vs_mcap!AD3*$D$4+crises_vs_mcap!AE3*$D$5+crises_vs_mcap!AF3*$D$6+crises_vs_mcap!AG3*$D$7) -> 0.048123745 | J37: =(N(crises_vs_mcap!AH3)*$D$2+N(crises_vs_mcap!AI3)*$D$3+N(crises_vs_mcap!AJ3)*$D$4+N(crises_vs_mcap!AK3)*$D$5+N(crises_vs_mcap!AL3)*$D$6+N(crises_vs_mcap!AM3)*$D$7)/(ISNUMBER(crises_vs_mcap!AH3)*$D$2+ISNUMBER(crises_vs_mcap!AI3)*$D$3+ISNUMBER(crises_vs_mcap!AJ3)*$D$4+ISNUMBER(crises_vs_mcap!AK3)*$D$5+ISNUMBER(crises_vs_mcap!AL3)*$D$6+ISNUMBER(crises_vs_mcap!AM3)*$D$7) -> 45.622287 | K37: =SUM(crises_vs_mcap!AZ3*$D$2+crises_vs_mcap!BA3*$D$3+crises_vs_mcap!BB3*$D$4+crises_vs_mcap!BC3*$D$5+crises_vs_mcap!BD3*$D$6+crises_vs_mcap!BE3*$D$7) -> -0.054789597 | L37: =SUM(crises_vs_mcap!BL3*$D$2+crises_vs_mcap!BM3*$D$3+crises_vs_mcap!BN3*$D$4+crises_vs_mcap!BO3*$D$5+crises_vs_mcap!BP3*$D$6+crises_vs_mcap!BQ3*$D$7) -> 0.074613208 | M37: =SUM(crises_vs_mcap!BR3*$D$2+crises_vs_mcap!BS3*$D$3+crises_vs_mcap!BT3*$D$4+crises_vs_mcap!BU3*$D$5+crises_vs_mcap!BV3*$D$6+crises_vs_mcap!BW3*$D$7) -> 0.036604813 | N37: =SUM(crises_vs_mcap!BX3*$D$2+crises_vs_mcap!BY3*$D$3+crises_vs_mcap!BZ3*$D$4+crises_vs_mcap!CA3*$D$5+crises_vs_mcap!CB3*$D$6+crises_vs_mcap!CC3*$D$7) -> -8.5898 | O37: =SUM(crises_vs_mcap!CD3*$D$2+crises_vs_mcap!CE3*$D$3+crises_vs_mcap!CF3*$D$4+crises_vs_mcap!CG3*$D$5+crises_vs_mcap!CH3*$D$6+crises_vs_mcap!CI3*$D$7) -> 0.042537903 | P37: =SUM(crises_vs_mcap!CJ3*$D$2+crises_vs_mcap!CK3*$D$3+crises_vs_mcap!CL3*$D$4+crises_vs_mcap!CM3*$D$5+crises_vs_mcap!CN3*$D$6+crises_vs_mcap!CO3*$D$7) -> -0.00018892349 | Q37: =(N(crises_vs_mcap!CP3)*$D$2+N(crises_vs_mcap!CQ3)*$D$3+N(crises_vs_mcap!CR3)*$D$4+N(crises_vs_mcap!CS3)*$D$5+N(crises_vs_mcap!CT3)*$D$6+N(crises_vs_mcap!CU3)*$D$7)/(ISNUMBER(crises_vs_mcap!CP3)*$D$2+ISNUMBER(crises_vs_mcap!CQ3)*$D$3+ISNUMBER(crises_vs_mcap!CR3)*$D$4+ISNUMBER(crises_vs_mcap!CS3)*$D$5+ISNUMBER(crises_vs_mcap!CT3)*$D$6+ISNUMBER(crises_vs_mcap!CU3)*$D$7) -> 62.41564 | R37: =SUM(crises_vs_mcap!CV3*$D$2+crises_vs_mcap!CW3*$D$3+crises_vs_mcap!CX3*$D$4+crises_vs_mcap!CY3*$D$5+crises_vs_mcap!CZ3*$D$6+crises_vs_mcap!DA3*$D$7) -> -0.12020371
A38: mvo | B38: mvo_t_10_lw | C38: monthly | D38: baseline | E38: none | F38: mvo_t_10_lw | G38: =SUM(crises_vs_mcap!J4*$D$2+crises_vs_mcap!K4*$D$3+crises_vs_mcap!L4*$D$4+crises_vs_mcap!M4*$D$5+crises_vs_mcap!N4*$D$6+crises_vs_mcap!O4*$D$7) -> 0.025505215 | H38: =SUM(crises_vs_mcap!P4*$D$2+crises_vs_mcap!Q4*$D$3+crises_vs_mcap!R4*$D$4+crises_vs_mcap!S4*$D$5+crises_vs_mcap!T4*$D$6+crises_vs_mcap!U4*$D$7) -> -0.0046542843 | I38: =SUM(crises_vs_mcap!AB4*$D$2+crises_vs_mcap!AC4*$D$3+crises_vs_mcap!AD4*$D$4+crises_vs_mcap!AE4*$D$5+crises_vs_mcap!AF4*$D$6+crises_vs_mcap!AG4*$D$7) -> -0.00035186121 | J38: =(N(crises_vs_mcap!AH4)*$D$2+N(crises_vs_mcap!AI4)*$D$3+N(crises_vs_mcap!AJ4)*$D$4+N(crises_vs_mcap!AK4)*$D$5+N(crises_vs_mcap!AL4)*$D$6+N(crises_vs_mcap!AM4)*$D$7)/(ISNUMBER(crises_vs_mcap!AH4)*$D$2+ISNUMBER(crises_vs_mcap!AI4)*$D$3+ISNUMBER(crises_vs_mcap!AJ4)*$D$4+ISNUMBER(crises_vs_mcap!AK4)*$D$5+ISNUMBER(crises_vs_mcap!AL4)*$D$6+ISNUMBER(crises_vs_mcap!AM4)*$D$7) -> -226.687 | K38: =SUM(crises_vs_mcap!AZ4*$D$2+crises_vs_mcap!BA4*$D$3+crises_vs_mcap!BB4*$D$4+crises_vs_mcap!BC4*$D$5+crises_vs_mcap!BD4*$D$6+crises_vs_mcap!BE4*$D$7) -> 0.018665904 | L38: =SUM(crises_vs_mcap!BL4*$D$2+crises_vs_mcap!BM4*$D$3+crises_vs_mcap!BN4*$D$4+crises_vs_mcap!BO4*$D$5+crises_vs_mcap!BP4*$D$6+crises_vs_mcap!BQ4*$D$7) -> -0.0041037073 | M38: =SUM(crises_vs_mcap!BR4*$D$2+crises_vs_mcap!BS4*$D$3+crises_vs_mcap!BT4*$D$4+crises_vs_mcap!BU4*$D$5+crises_vs_mcap!BV4*$D$6+crises_vs_mcap!BW4*$D$7) -> -0.0061825542 | N38: =SUM(crises_vs_mcap!BX4*$D$2+crises_vs_mcap!BY4*$D$3+crises_vs_mcap!BZ4*$D$4+crises_vs_mcap!CA4*$D$5+crises_vs_mcap!CB4*$D$6+crises_vs_mcap!CC4*$D$7) -> -0.0504 | O38: =SUM(crises_vs_mcap!CD4*$D$2+crises_vs_mcap!CE4*$D$3+crises_vs_mcap!CF4*$D$4+crises_vs_mcap!CG4*$D$5+crises_vs_mcap!CH4*$D$6+crises_vs_mcap!CI4*$D$7) -> 0.029773486 | P38: =SUM(crises_vs_mcap!CJ4*$D$2+crises_vs_mcap!CK4*$D$3+crises_vs_mcap!CL4*$D$4+crises_vs_mcap!CM4*$D$5+crises_vs_mcap!CN4*$D$6+crises_vs_mcap!CO4*$D$7) -> 0.0081543825 | Q38: =(N(crises_vs_mcap!CP4)*$D$2+N(crises_vs_mcap!CQ4)*$D$3+N(crises_vs_mcap!CR4)*$D$4+N(crises_vs_mcap!CS4)*$D$5+N(crises_vs_mcap!CT4)*$D$6+N(crises_vs_mcap!CU4)*$D$7)/(ISNUMBER(crises_vs_mcap!CP4)*$D$2+ISNUMBER(crises_vs_mcap!CQ4)*$D$3+ISNUMBER(crises_vs_mcap!CR4)*$D$4+ISNUMBER(crises_vs_mcap!CS4)*$D$5+ISNUMBER(crises_vs_mcap!CT4)*$D$6+ISNUMBER(crises_vs_mcap!CU4)*$D$7) -> -226.58847 | R38: =SUM(crises_vs_mcap!CV4*$D$2+crises_vs_mcap!CW4*$D$3+crises_vs_mcap!CX4*$D$4+crises_vs_mcap!CY4*$D$5+crises_vs_mcap!CZ4*$D$6+crises_vs_mcap!DA4*$D$7) -> 0.024852163
A39: hrp | B39: hrp_t_10_lw_ward | C39: monthly | D39: baseline | E39: none | F39: hrp_t_10_lw_ward | G39: =SUM(crises_vs_mcap!J5*$D$2+crises_vs_mcap!K5*$D$3+crises_vs_mcap!L5*$D$4+crises_vs_mcap!M5*$D$5+crises_vs_mcap!N5*$D$6+crises_vs_mcap!O5*$D$7) -> 0.26287645 | H39: =SUM(crises_vs_mcap!P5*$D$2+crises_vs_mcap!Q5*$D$3+crises_vs_mcap!R5*$D$4+crises_vs_mcap!S5*$D$5+crises_vs_mcap!T5*$D$6+crises_vs_mcap!U5*$D$7) -> 0.10024086 | I39: =SUM(crises_vs_mcap!AB5*$D$2+crises_vs_mcap!AC5*$D$3+crises_vs_mcap!AD5*$D$4+crises_vs_mcap!AE5*$D$5+crises_vs_mcap!AF5*$D$6+crises_vs_mcap!AG5*$D$7) -> 0.11940519 | J39: =(N(crises_vs_mcap!AH5)*$D$2+N(crises_vs_mcap!AI5)*$D$3+N(crises_vs_mcap!AJ5)*$D$4+N(crises_vs_mcap!AK5)*$D$5+N(crises_vs_mcap!AL5)*$D$6+N(crises_vs_mcap!AM5)*$D$7)/(ISNUMBER(crises_vs_mcap!AH5)*$D$2+ISNUMBER(crises_vs_mcap!AI5)*$D$3+ISNUMBER(crises_vs_mcap!AJ5)*$D$4+ISNUMBER(crises_vs_mcap!AK5)*$D$5+ISNUMBER(crises_vs_mcap!AL5)*$D$6+ISNUMBER(crises_vs_mcap!AM5)*$D$7) -> -99.423265 | K39: =SUM(crises_vs_mcap!AZ5*$D$2+crises_vs_mcap!BA5*$D$3+crises_vs_mcap!BB5*$D$4+crises_vs_mcap!BC5*$D$5+crises_vs_mcap!BD5*$D$6+crises_vs_mcap!BE5*$D$7) -> -0.096521994 | L39: =SUM(crises_vs_mcap!BL5*$D$2+crises_vs_mcap!BM5*$D$3+crises_vs_mcap!BN5*$D$4+crises_vs_mcap!BO5*$D$5+crises_vs_mcap!BP5*$D$6+crises_vs_mcap!BQ5*$D$7) -> 0.23860152 | M39: =SUM(crises_vs_mcap!BR5*$D$2+crises_vs_mcap!BS5*$D$3+crises_vs_mcap!BT5*$D$4+crises_vs_mcap!BU5*$D$5+crises_vs_mcap!BV5*$D$6+crises_vs_mcap!BW5*$D$7) -> 0.098148275 | N39: =SUM(crises_vs_mcap!BX5*$D$2+crises_vs_mcap!BY5*$D$3+crises_vs_mcap!BZ5*$D$4+crises_vs_mcap!CA5*$D$5+crises_vs_mcap!CB5*$D$6+crises_vs_mcap!CC5*$D$7) -> -8.5898 | O39: =SUM(crises_vs_mcap!CD5*$D$2+crises_vs_mcap!CE5*$D$3+crises_vs_mcap!CF5*$D$4+crises_vs_mcap!CG5*$D$5+crises_vs_mcap!CH5*$D$6+crises_vs_mcap!CI5*$D$7) -> 0.017538365 | P39: =SUM(crises_vs_mcap!CJ5*$D$2+crises_vs_mcap!CK5*$D$3+crises_vs_mcap!CL5*$D$4+crises_vs_mcap!CM5*$D$5+crises_vs_mcap!CN5*$D$6+crises_vs_mcap!CO5*$D$7) -> 0.023465029 | Q39: =(N(crises_vs_mcap!CP5)*$D$2+N(crises_vs_mcap!CQ5)*$D$3+N(crises_vs_mcap!CR5)*$D$4+N(crises_vs_mcap!CS5)*$D$5+N(crises_vs_mcap!CT5)*$D$6+N(crises_vs_mcap!CU5)*$D$7)/(ISNUMBER(crises_vs_mcap!CP5)*$D$2+ISNUMBER(crises_vs_mcap!CQ5)*$D$3+ISNUMBER(crises_vs_mcap!CR5)*$D$4+ISNUMBER(crises_vs_mcap!CS5)*$D$5+ISNUMBER(crises_vs_mcap!CT5)*$D$6+ISNUMBER(crises_vs_mcap!CU5)*$D$7) -> -82.629912 | R39: =SUM(crises_vs_mcap!CV5*$D$2+crises_vs_mcap!CW5*$D$3+crises_vs_mcap!CX5*$D$4+crises_vs_mcap!CY5*$D$5+crises_vs_mcap!CZ5*$D$6+crises_vs_mcap!DA5*$D$7) -> -0.32843701
A40: xgb | B40: xgb_t_10_holdout | C40: monthly | D40: baseline | E40: none | F40: xgb_t_10_holdout | G40: =SUM(crises_vs_mcap!J6*$D$2+crises_vs_mcap!K6*$D$3+crises_vs_mcap!L6*$D$4+crises_vs_mcap!M6*$D$5+crises_vs_mcap!N6*$D$6+crises_vs_mcap!O6*$D$7) -> 0.12932764 | H40: =SUM(crises_vs_mcap!P6*$D$2+crises_vs_mcap!Q6*$D$3+crises_vs_mcap!R6*$D$4+crises_vs_mcap!S6*$D$5+crises_vs_mcap!T6*$D$6+crises_vs_mcap!U6*$D$7) -> 0.019446505 | I40: =SUM(crises_vs_mcap!AB6*$D$2+crises_vs_mcap!AC6*$D$3+crises_vs_mcap!AD6*$D$4+crises_vs_mcap!AE6*$D$5+crises_vs_mcap!AF6*$D$6+crises_vs_mcap!AG6*$D$7) -> 0.027121949 | J40: =(N(crises_vs_mcap!AH6)*$D$2+N(crises_vs_mcap!AI6)*$D$3+N(crises_vs_mcap!AJ6)*$D$4+N(crises_vs_mcap!AK6)*$D$5+N(crises_vs_mcap!AL6)*$D$6+N(crises_vs_mcap!AM6)*$D$7)/(ISNUMBER(crises_vs_mcap!AH6)*$D$2+ISNUMBER(crises_vs_mcap!AI6)*$D$3+ISNUMBER(crises_vs_mcap!AJ6)*$D$4+ISNUMBER(crises_vs_mcap!AK6)*$D$5+ISNUMBER(crises_vs_mcap!AL6)*$D$6+ISNUMBER(crises_vs_mcap!AM6)*$D$7) -> 66.34174 | K40: =SUM(crises_vs_mcap!AZ6*$D$2+crises_vs_mcap!BA6*$D$3+crises_vs_mcap!BB6*$D$4+crises_vs_mcap!BC6*$D$5+crises_vs_mcap!BD6*$D$6+crises_vs_mcap!BE6*$D$7) -> -0.052771279 | L40: =SUM(crises_vs_mcap!BL6*$D$2+crises_vs_mcap!BM6*$D$3+crises_vs_mcap!BN6*$D$4+crises_vs_mcap!BO6*$D$5+crises_vs_mcap!BP6*$D$6+crises_vs_mcap!BQ6*$D$7) -> 0.031152317 | M40: =SUM(crises_vs_mcap!BR6*$D$2+crises_vs_mcap!BS6*$D$3+crises_vs_mcap!BT6*$D$4+crises_vs_mcap!BU6*$D$5+crises_vs_mcap!BV6*$D$6+crises_vs_mcap!BW6*$D$7) -> 0.017416008 | N40: =SUM(crises_vs_mcap!BX6*$D$2+crises_vs_mcap!BY6*$D$3+crises_vs_mcap!BZ6*$D$4+crises_vs_mcap!CA6*$D$5+crises_vs_mcap!CB6*$D$6+crises_vs_mcap!CC6*$D$7) -> 18.0254 | O40: =SUM(crises_vs_mcap!CD6*$D$2+crises_vs_mcap!CE6*$D$3+crises_vs_mcap!CF6*$D$4+crises_vs_mcap!CG6*$D$5+crises_vs_mcap!CH6*$D$6+crises_vs_mcap!CI6*$D$7) -> 0.10141539 | P40: =SUM(crises_vs_mcap!CJ6*$D$2+crises_vs_mcap!CK6*$D$3+crises_vs_mcap!CL6*$D$4+crises_vs_mcap!CM6*$D$5+crises_vs_mcap!CN6*$D$6+crises_vs_mcap!CO6*$D$7) -> -0.012006626 | Q40: =(N(crises_vs_mcap!CP6)*$D$2+N(crises_vs_mcap!CQ6)*$D$3+N(crises_vs_mcap!CR6)*$D$4+N(crises_vs_mcap!CS6)*$D$5+N(crises_vs_mcap!CT6)*$D$6+N(crises_vs_mcap!CU6)*$D$7)/(ISNUMBER(crises_vs_mcap!CP6)*$D$2+ISNUMBER(crises_vs_mcap!CQ6)*$D$3+ISNUMBER(crises_vs_mcap!CR6)*$D$4+ISNUMBER(crises_vs_mcap!CS6)*$D$5+ISNUMBER(crises_vs_mcap!CT6)*$D$6+ISNUMBER(crises_vs_mcap!CU6)*$D$7) -> 83.617595 | R40: =SUM(crises_vs_mcap!CV6*$D$2+crises_vs_mcap!CW6*$D$3+crises_vs_mcap!CX6*$D$4+crises_vs_mcap!CY6*$D$5+crises_vs_mcap!CZ6*$D$6+crises_vs_mcap!DA6*$D$7) -> -0.016429176
A41: rf | B41: rf_t_10_holdout | C41: monthly | D41: baseline | E41: none | F41: rf_t_10_holdout | G41: =SUM(crises_vs_mcap!J7*$D$2+crises_vs_mcap!K7*$D$3+crises_vs_mcap!L7*$D$4+crises_vs_mcap!M7*$D$5+crises_vs_mcap!N7*$D$6+crises_vs_mcap!O7*$D$7) -> 0.14319757 | H41: =SUM(crises_vs_mcap!P7*$D$2+crises_vs_mcap!Q7*$D$3+crises_vs_mcap!R7*$D$4+crises_vs_mcap!S7*$D$5+crises_vs_mcap!T7*$D$6+crises_vs_mcap!U7*$D$7) -> 0.014418449 | I41: =SUM(crises_vs_mcap!AB7*$D$2+crises_vs_mcap!AC7*$D$3+crises_vs_mcap!AD7*$D$4+crises_vs_mcap!AE7*$D$5+crises_vs_mcap!AF7*$D$6+crises_vs_mcap!AG7*$D$7) -> 0.02373971 | J41: =(N(crises_vs_mcap!AH7)*$D$2+N(crises_vs_mcap!AI7)*$D$3+N(crises_vs_mcap!AJ7)*$D$4+N(crises_vs_mcap!AK7)*$D$5+N(crises_vs_mcap!AL7)*$D$6+N(crises_vs_mcap!AM7)*$D$7)/(ISNUMBER(crises_vs_mcap!AH7)*$D$2+ISNUMBER(crises_vs_mcap!AI7)*$D$3+ISNUMBER(crises_vs_mcap!AJ7)*$D$4+ISNUMBER(crises_vs_mcap!AK7)*$D$5+ISNUMBER(crises_vs_mcap!AL7)*$D$6+ISNUMBER(crises_vs_mcap!AM7)*$D$7) -> 95.4565 | K41: =SUM(crises_vs_mcap!AZ7*$D$2+crises_vs_mcap!BA7*$D$3+crises_vs_mcap!BB7*$D$4+crises_vs_mcap!BC7*$D$5+crises_vs_mcap!BD7*$D$6+crises_vs_mcap!BE7*$D$7) -> -0.048795008 | L41: =SUM(crises_vs_mcap!BL7*$D$2+crises_vs_mcap!BM7*$D$3+crises_vs_mcap!BN7*$D$4+crises_vs_mcap!BO7*$D$5+crises_vs_mcap!BP7*$D$6+crises_vs_mcap!BQ7*$D$7) -> 0.026807667 | M41: =SUM(crises_vs_mcap!BR7*$D$2+crises_vs_mcap!BS7*$D$3+crises_vs_mcap!BT7*$D$4+crises_vs_mcap!BU7*$D$5+crises_vs_mcap!BV7*$D$6+crises_vs_mcap!BW7*$D$7) -> 0.012462511 | N41: =SUM(crises_vs_mcap!BX7*$D$2+crises_vs_mcap!BY7*$D$3+crises_vs_mcap!BZ7*$D$4+crises_vs_mcap!CA7*$D$5+crises_vs_mcap!CB7*$D$6+crises_vs_mcap!CC7*$D$7) -> 18.0254 | O41: =SUM(crises_vs_mcap!CD7*$D$2+crises_vs_mcap!CE7*$D$3+crises_vs_mcap!CF7*$D$4+crises_vs_mcap!CG7*$D$5+crises_vs_mcap!CH7*$D$6+crises_vs_mcap!CI7*$D$7) -> 0.11273305 | P41: =SUM(crises_vs_mcap!CJ7*$D$2+crises_vs_mcap!CK7*$D$3+crises_vs_mcap!CL7*$D$4+crises_vs_mcap!CM7*$D$5+crises_vs_mcap!CN7*$D$6+crises_vs_mcap!CO7*$D$7) -> -0.013497644 | Q41: =(N(crises_vs_mcap!CP7)*$D$2+N(crises_vs_mcap!CQ7)*$D$3+N(crises_vs_mcap!CR7)*$D$4+N(crises_vs_mcap!CS7)*$D$5+N(crises_vs_mcap!CT7)*$D$6+N(crises_vs_mcap!CU7)*$D$7)/(ISNUMBER(crises_vs_mcap!CP7)*$D$2+ISNUMBER(crises_vs_mcap!CQ7)*$D$3+ISNUMBER(crises_vs_mcap!CR7)*$D$4+ISNUMBER(crises_vs_mcap!CS7)*$D$5+ISNUMBER(crises_vs_mcap!CT7)*$D$6+ISNUMBER(crises_vs_mcap!CU7)*$D$7) -> 112.73236 | R41: =SUM(crises_vs_mcap!CV7*$D$2+crises_vs_mcap!CW7*$D$3+crises_vs_mcap!CX7*$D$4+crises_vs_mcap!CY7*$D$5+crises_vs_mcap!CZ7*$D$6+crises_vs_mcap!DA7*$D$7) -> -0.014767041
A42: lstm | B42: lstm_t_10_holdout_rank | C42: monthly | D42: baseline | E42: none | F42: lstm_t_10_holdout_rank | G42: =SUM(crises_vs_mcap!J8*$D$2+crises_vs_mcap!K8*$D$3+crises_vs_mcap!L8*$D$4+crises_vs_mcap!M8*$D$5+crises_vs_mcap!N8*$D$6+crises_vs_mcap!O8*$D$7) -> 0.1551194 | H42: =SUM(crises_vs_mcap!P8*$D$2+crises_vs_mcap!Q8*$D$3+crises_vs_mcap!R8*$D$4+crises_vs_mcap!S8*$D$5+crises_vs_mcap!T8*$D$6+crises_vs_mcap!U8*$D$7) -> 0.0020055313 | I42: =SUM(crises_vs_mcap!AB8*$D$2+crises_vs_mcap!AC8*$D$3+crises_vs_mcap!AD8*$D$4+crises_vs_mcap!AE8*$D$5+crises_vs_mcap!AF8*$D$6+crises_vs_mcap!AG8*$D$7) -> 0.013353925 | J42: =(N(crises_vs_mcap!AH8)*$D$2+N(crises_vs_mcap!AI8)*$D$3+N(crises_vs_mcap!AJ8)*$D$4+N(crises_vs_mcap!AK8)*$D$5+N(crises_vs_mcap!AL8)*$D$6+N(crises_vs_mcap!AM8)*$D$7)/(ISNUMBER(crises_vs_mcap!AH8)*$D$2+ISNUMBER(crises_vs_mcap!AI8)*$D$3+ISNUMBER(crises_vs_mcap!AJ8)*$D$4+ISNUMBER(crises_vs_mcap!AK8)*$D$5+ISNUMBER(crises_vs_mcap!AL8)*$D$6+ISNUMBER(crises_vs_mcap!AM8)*$D$7) -> 93.939785 | K42: =SUM(crises_vs_mcap!AZ8*$D$2+crises_vs_mcap!BA8*$D$3+crises_vs_mcap!BB8*$D$4+crises_vs_mcap!BC8*$D$5+crises_vs_mcap!BD8*$D$6+crises_vs_mcap!BE8*$D$7) -> -0.041855671 | L42: =SUM(crises_vs_mcap!BL8*$D$2+crises_vs_mcap!BM8*$D$3+crises_vs_mcap!BN8*$D$4+crises_vs_mcap!BO8*$D$5+crises_vs_mcap!BP8*$D$6+crises_vs_mcap!BQ8*$D$7) -> 0.0051046949 | M42: =SUM(crises_vs_mcap!BR8*$D$2+crises_vs_mcap!BS8*$D$3+crises_vs_mcap!BT8*$D$4+crises_vs_mcap!BU8*$D$5+crises_vs_mcap!BV8*$D$6+crises_vs_mcap!BW8*$D$7) -> 0.00050210713 | N42: =SUM(crises_vs_mcap!BX8*$D$2+crises_vs_mcap!BY8*$D$3+crises_vs_mcap!BZ8*$D$4+crises_vs_mcap!CA8*$D$5+crises_vs_mcap!CB8*$D$6+crises_vs_mcap!CC8*$D$7) -> 20.0988 | O42: =SUM(crises_vs_mcap!CD8*$D$2+crises_vs_mcap!CE8*$D$3+crises_vs_mcap!CF8*$D$4+crises_vs_mcap!CG8*$D$5+crises_vs_mcap!CH8*$D$6+crises_vs_mcap!CI8*$D$7) -> 0.14517705 | P42: =SUM(crises_vs_mcap!CJ8*$D$2+crises_vs_mcap!CK8*$D$3+crises_vs_mcap!CL8*$D$4+crises_vs_mcap!CM8*$D$5+crises_vs_mcap!CN8*$D$6+crises_vs_mcap!CO8*$D$7) -> -0.012972195 | Q42: =(N(crises_vs_mcap!CP8)*$D$2+N(crises_vs_mcap!CQ8)*$D$3+N(crises_vs_mcap!CR8)*$D$4+N(crises_vs_mcap!CS8)*$D$5+N(crises_vs_mcap!CT8)*$D$6+N(crises_vs_mcap!CU8)*$D$7)/(ISNUMBER(crises_vs_mcap!CP8)*$D$2+ISNUMBER(crises_vs_mcap!CQ8)*$D$3+ISNUMBER(crises_vs_mcap!CR8)*$D$4+ISNUMBER(crises_vs_mcap!CS8)*$D$5+ISNUMBER(crises_vs_mcap!CT8)*$D$6+ISNUMBER(crises_vs_mcap!CU8)*$D$7) -> 107.16207 | R42: =SUM(crises_vs_mcap!CV8*$D$2+crises_vs_mcap!CW8*$D$3+crises_vs_mcap!CX8*$D$4+crises_vs_mcap!CY8*$D$5+crises_vs_mcap!CZ8*$D$6+crises_vs_mcap!DA8*$D$7) -> 0.019636137
A44: VIX Weighted Crises
A45: model | B45: run | C45: frequency | D45: role | E45: detector | F45: base_run | G45: vix_crisis_exc_ret_full_fix | H45: vix_crisis_exc_dd_full_fix | I45: vix_crisis_exc_dd_full_flex | J45: vix_crisis_exc_days_full_flex | K45: vix_crisis_exc_ulcer_full_flex | L45: vix_crisis_exc_ret_ptt_fix | M45: vix_crisis_exc_dd_ptt_fix | N45: vix_crisis_exc_days_ptt_flex | O45: vix_crisis_exc_ret_ttp_fix | P45: vix_crisis_exc_dd_ttp_fix | Q45: vix_crisis_exc_days_ttp_flex | R45: vix_exc_crisis_ret_to_even_ttp_flex
